Workbook

Sheet Capital Costs - R2
A1: AEO2025 Reference Case
A2: From EIA
A5: 55. Overnight Capital Costs for New Electricity Generating Plants
A6: (2024 dollars per kilowatt)
A8: Technology | B8: 2010 | C8: 2011 | D8: 2012 | E8: 2013 | F8: 2014 | G8: 2015 | H8: 2016 | I8: 2017 | J8: 2018 | K8: 2019 | L8: 2020 | M8: 2021 | N8: 2022 | O8: 2023 | P8: 2024 | Q8: 2025 | R8: 2026 | S8: 2027 | T8: 2028 | U8: 2029 | V8: 2030 | W8: 2031 | X8: 2032 | Y8: 2033 | Z8: 2034 | AA8: 2035 | AB8: 2036 | AC8: 2037 | AD8: 2038 | AE8: 2039 | AF8: 2040 | AG8: 2041 | AH8: 2042 | AI8: 2043 | AJ8: 2044 | AK8: 2045 | AL8: 2046 | AM8: 2047 | AN8: 2048 | AO8: 2049 | AP8: 2050
A10: Coal
A11: USC Coal with Partial Carbon Capture | E11: 0 | F11: 0 | G11: 0 | H11: 0 | I11: 0 | J11: 0 | K11: 0 | L11: 0 | M11: 0 | N11: 0 | O11: 0 | P11: 0 | Q11: 5211.9351 | R11: 5089.1191 | S11: 5010.0088 | T11: 4925.5928 | U11: 4867.5176 | V11: 4825.4814 | W11: 4797.8794 | X11: 4768.2959 | Y11: 4734.5864 | Z11: 4596.1396 | AA11: 4550.2231 | AB11: 4392.9399 | AC11: 4312.4917 | AD11: 4261.4907 | AE11: 4220.6504 | AF11: 4190.9443 | AG11: 4161.0781 | AH11: 4130.9932 | AI11: 4098.2388 | AJ11: 4063.3245 | AK11: 4029.49 | AL11: 3993.6074 | AM11: 3960.3872 | AN11: 3931.4434 | AO11: 3902.8464 | AP11: 3872.8923
A12: USC Coal with Carbon Capture | E12: 0 | F12: 0 | G12: 0 | H12: 0 | I12: 0 | J12: 0 | K12: 0 | L12: 0 | M12: 0 | N12: 0 | O12: 0 | P12: 0 | Q12: 7338.9448 | R12: 7163.2148 | S12: 7049.0889 | T12: 6927.5664 | U12: 6843.147 | V12: 6781.3091 | W12: 6739.7925 | X12: 6695.4805 | Y12: 6645.3862 | Z12: 6312.3965 | AA12: 6246.2466 | AB12: 5867.623 | AC12: 5689.0449 | AD12: 5586.8647 | AE12: 5515.3789 | AF12: 5472.7231 | AG12: 5429.8755 | AH12: 5386.7627 | AI12: 5340.1904 | AJ12: 5290.8301 | AK12: 5242.9048 | AL12: 5192.3442 | AM12: 5145.2739 | AN12: 5103.7832 | AO12: 5062.7607 | AP12: 5019.998
A13: Combined Cycle
A14: Combined Cycle - Single Shaft | E14: 0 | F14: 0 | G14: 0 | H14: 0 | I14: 0 | J14: 0 | K14: 0 | L14: 0 | M14: 0 | N14: 0 | O14: 0 | P14: 0 | Q14: 874.81812 | R14: 855.32361 | S14: 840.4649 | T14: 824.00958 | U14: 812.27319 | V14: 804.03394 | W14: 797.99945 | X14: 791.99725 | Y14: 785.32043 | Z14: 774.1355 | AA14: 766.98035 | AB14: 760.87158 | AC14: 756.18939 | AD14: 752.4751 | AE14: 748.56952 | AF14: 744.52637 | AG14: 739.73529 | AH14: 735.82697 | AI14: 731.57294 | AJ14: 726.9223 | AK14: 722.45331 | AL14: 717.60492 | AM14: 713.22308 | AN14: 709.60187 | AO14: 706.03552 | AP14: 702.21564
A15: Combined Cycle - Multi Shaft | E15: 0 | F15: 0 | G15: 0 | H15: 0 | I15: 0 | J15: 0 | K15: 0 | L15: 0 | M15: 0 | N15: 0 | O15: 0 | P15: 0 | Q15: 824.17456 | R15: 805.80859 | S15: 791.81012 | T15: 776.30737 | U15: 765.25049 | V15: 757.48816 | W15: 751.80298 | X15: 746.14825 | Y15: 739.85803 | Z15: 729.32056 | AA15: 722.57953 | AB15: 716.82446 | AC15: 712.41339 | AD15: 708.91406 | AE15: 705.23456 | AF15: 701.42554 | AG15: 696.9118 | AH15: 693.2298 | AI15: 689.22192 | AJ15: 684.84052 | AK15: 680.63025 | AL15: 676.06262 | AM15: 671.93433 | AN15: 668.52277 | AO15: 665.1629 | AP15: 661.56415
A16: Combined Cycle with Carbon Capture | E16: 0 | F16: 0 | G16: 0 | H16: 0 | I16: 0 | J16: 0 | K16: 0 | L16: 0 | M16: 0 | N16: 0 | O16: 0 | P16: 0 | Q16: 2469.3091 | R16: 2409.6323 | S16: 2366.1619 | T16: 2319.0688 | U16: 2284.9749 | V16: 2259.8416 | W16: 2241.1741 | X16: 2222.1785 | Y16: 2201.2932 | Z16: 1992.7914 | AA16: 1970.1451 | AB16: 1747.0607 | AC16: 1649.261 | AD16: 1597.3977 | AE16: 1566.4044 | AF16: 1552.8246 | AG16: 1538.0975 | AH16: 1524.7324 | AI16: 1510.6069 | AJ16: 1495.6992 | AK16: 1481.2043 | AL16: 1465.9719 | AM16: 1451.7324 | AN16: 1439.0726 | AO16: 1426.5496 | AP16: 1413.541
A17: Combustion Turbine/Diesel
A18: Combustion Turbine - Aeroderivative | E18: 0 | F18: 0 | G18: 0 | H18: 0 | I18: 0 | J18: 0 | K18: 0 | L18: 0 | M18: 0 | N18: 0 | O18: 0 | P18: 0 | Q18: 1521.5192 | R18: 1486.0873 | S18: 1453.0079 | T18: 1415.4216 | U18: 1387.1853 | V18: 1367.1274 | W18: 1350.3821 | X18: 1334.3231 | Y18: 1317.1018 | Z18: 1284.571 | AA18: 1270.1995 | AB18: 1257.8202 | AC18: 1247.676 | AD18: 1240.4026 | AE18: 1233.0972 | AF18: 1224.9203 | AG18: 1214.2035 | AH18: 1206.6582 | AI18: 1198.8073 | AJ18: 1190.3125 | AK18: 1182.1216 | AL18: 1173.3168 | AM18: 1165.281 | AN18: 1158.4934 | AO18: 1151.7994 | AP18: 1144.6963
A19: Combustion Turbine - Industrial Frame | E19: 0 | F19: 0 | G19: 0 | H19: 0 | I19: 0 | J19: 0 | K19: 0 | L19: 0 | M19: 0 | N19: 0 | O19: 0 | P19: 0 | Q19: 791.0802 | R19: 772.6582 | S19: 755.45929 | T19: 735.91705 | U19: 721.23633 | V19: 710.80768 | W19: 702.1012 | X19: 693.75171 | Y19: 684.79791 | Z19: 667.88428 | AA19: 660.41211 | AB19: 653.97571 | AC19: 648.70154 | AD19: 644.91974 | AE19: 641.12152 | AF19: 636.87018 | AG19: 631.29822 | AH19: 627.37518 | AI19: 623.29327 | AJ19: 618.87665 | AK19: 614.61792 | AL19: 610.04004 | AM19: 605.86206 | AN19: 602.33289 | AO19: 598.8526 | AP19: 595.15942
A20: Nuclear Power
A21: Light Water Reactor | E21: 0 | F21: 0 | G21: 0 | H21: 0 | I21: 0 | J21: 0 | K21: 0 | L21: 0 | M21: 0 | N21: 0 | O21: 0 | P21: 0 | Q21: 7821.3379 | R21: 7570.0195 | S21: 7425.5059 | T21: 7273.7793 | U21: 7161.4932 | V21: 7073.1221 | W21: 7006.2744 | X21: 6936.4048 | Y21: 6860.6523 | Z21: 6777.168 | AA21: 6683.1533 | AB21: 6597.4575 | AC21: 6525.0132 | AD21: 6455.146 | AE21: 6382.5229 | AF21: 6311.9253 | AG21: 6241.209 | AH21: 6170.2915 | AI21: 6095.5332 | AJ21: 6017.7412 | AK21: 5941.7378 | AL21: 5862.9116 | AM21: 5788.1909 | AN21: 5719.8745 | AO21: 5652.188 | AP21: 5582.6694
A22: Small Modular Reactor | E22: 0 | F22: 0 | G22: 0 | H22: 0 | I22: 0 | J22: 0 | K22: 0 | L22: 0 | M22: 0 | N22: 0 | O22: 0 | P22: 0 | Q22: 9314.1123 | R22: 9062.6367 | S22: 8889.9902 | T22: 8708.6973 | U22: 8574.6191 | V22: 8469.1709 | W22: 8389.4922 | X22: 8306.1934 | Y22: 8215.8486 | Z22: 8116.2417 | AA22: 8004.02 | AB22: 7901.7593 | AC22: 7815.3662 | AD22: 7732.0581 | AE22: 7645.4478 | AF22: 7561.2617 | AG22: 7476.9307 | AH22: 7392.3579 | AI22: 7303.1802 | AJ22: 7210.3657 | AK22: 7119.6914 | AL22: 7025.6318 | AM22: 6936.4888 | AN22: 6855.0181 | AO22: 6774.2998 | AP22: 6691.3848
A23: Fuel Cells | E23: 0 | F23: 0 | G23: 0 | H23: 0 | I23: 0 | J23: 0 | K23: 0 | L23: 0 | M23: 0 | N23: 0 | O23: 0 | P23: 0 | Q23: 7895.6562 | R23: 7621.749 | S23: 7476.2822 | T23: 7323.5518 | U23: 7139.7891 | V23: 7045.4585 | W23: 6978.6753 | X23: 6908.8833 | Y23: 6833.2329 | Z23: 6749.8818 | AA23: 6656.0444 | AB23: 6570.4961 | AC23: 6498.145 | AD23: 6428.3618 | AE23: 6355.8345 | AF23: 6285.3262 | AG23: 6214.7002 | AH23: 6143.875 | AI23: 6069.2261 | AJ23: 5991.5586 | AK23: 5915.6729 | AL23: 5836.98 | AM23: 5762.3745 | AN23: 5694.147 | AO23: 5626.5464 | AP23: 5557.124
A24: Hydrogen Turbine | P24: 0 | Q24: 823.36688 | R24: 804.0401 | S24: 786.27136 | T24: 766.1474 | U24: 751.03894 | V24: 740.26135 | W24: 731.3006 | X24: 722.6767 | Y24: 713.42407 | Z24: 691.47333 | AA24: 677.72449 | AB24: 666.32263 | AC24: 659.09222 | AD24: 653.54913 | AE24: 649.45819 | AF24: 644.92499 | AG24: 638.38654 | AH24: 634.18048 | AI24: 629.80969 | AJ24: 625.10229 | AK24: 620.55627 | AL24: 615.68982 | AM24: 611.22882 | AN24: 607.42389 | AO24: 603.66925 | AP24: 599.70142
A25: Renewable Sources
A26: Conventional Hydroelectric Power 1/ | E26: 0 | F26: 0 | G26: 0 | H26: 0 | I26: 0 | J26: 0 | K26: 0 | L26: 0 | M26: 0 | N26: 0 | O26: 0 | P26: 0 | Q26: 3089.5334 | R26: 3023.7649 | S26: 2983.7441 | T26: 2940.3953 | U26: 2912.6301 | V26: 2894.3792 | W26: 2884.8342 | X26: 2873.9883 | Y26: 1540.7435 | Z26: 1531.7439 | AA26: 1520.2715 | AB26: 1510.5929 | AC26: 1758.6165 | AD26: 1751.4073 | AE26: 1743.395 | AF26: 1735.8778 | AG26: 1728.2716 | AH26: 1720.551 | AI26: 1711.6915 | AJ26: 1701.8966 | AK26: 1692.519 | AL26: 1682.2445 | AM26: 1673.0553 | AN26: 1665.6444 | AO26: 1658.3568 | AP26: 1650.4679
A27: Geothermal 1/ | E27: 0 | F27: 0 | G27: 0 | H27: 0 | I27: 0 | J27: 0 | K27: 0 | L27: 0 | M27: 0 | N27: 0 | O27: 0 | P27: 0 | Q27: 3097.2878 | R27: 3025.4802 | S27: 2950.3057 | T27: 2901.7429 | U27: 2809.2961 | V27: 2766.3713 | W27: 2702.8689 | X27: 2700.0317 | Y27: 2639.95 | Z27: 2526.1714 | AA27: 2475.7117 | AB27: 2435.7202 | AC27: 3109.124 | AD27: 3072.627 | AE27: 3671.761 | AF27: 3630.7983 | AG27: 3590.9885 | AH27: 3556.2625 | AI27: 3523.1465 | AJ27: 3491.5825 | AK27: 3444.9753 | AL27: 3705.376 | AM27: 3674.9736 | AN27: 3648.5371 | AO27: 3622.4204 | AP27: 3595.042
A28: Wood and Other Biomass | E28: 0 | F28: 0 | G28: 0 | H28: 0 | I28: 0 | J28: 0 | K28: 0 | L28: 0 | M28: 0 | N28: 0 | O28: 0 | P28: 0 | Q28: 4570.6011 | R28: 4464.6357 | S28: 4396.958 | T28: 4324.5825 | U28: 4275.2988 | V28: 4240.0825 | W28: 4217.668 | X28: 4193.3779 | Y28: 4165.4502 | Z28: 4132.7085 | AA28: 4093.3748 | AB28: 4058.9561 | AC28: 4032.5632 | AD28: 4007.6787 | AE28: 3980.9958 | AF28: 3955.4846 | AG28: 3929.8101 | AH28: 3903.9167 | AI28: 3875.4863 | AJ28: 3844.9956 | AK28: 3815.509 | AL28: 3784.063 | AM28: 3755.1206 | AN28: 3730.2185 | AO28: 3705.6328 | AP28: 3679.7456
A29: Biomass Energy with Carbon Capture | P29: 0 | Q29: 12889.833 | R29: 12576.279 | S29: 12371.036 | T29: 12152.931 | U29: 12000.012 | V29: 11886.749 | W29: 11809.457 | X29: 11726.962 | Y29: 11634.359 | Z29: 10814.114 | AA29: 10695.316 | AB29: 9769.0869 | AC29: 9349.9014 | AD29: 9119.5391 | AE29: 8970.5557 | AF29: 8894.249 | AG29: 8817.666 | AH29: 8740.6836 | AI29: 8658.1279 | AJ29: 8571.0996 | AK29: 8486.4492 | AL29: 8397.584 | AM29: 8314.4209 | AN29: 8240.3125 | AO29: 8166.9966 | AP29: 8090.9077
A30: Solar Photovoltaic with Axis Tracking | E30: 0 | F30: 0 | G30: 0 | H30: 0 | I30: 0 | J30: 0 | K30: 0 | L30: 0 | M30: 0 | N30: 0 | O30: 0 | P30: 0 | Q30: 1379.3601 | R30: 1278.5338 | S30: 1229.4457 | T30: 1185.405 | U30: 1165.9803 | V30: 1149.6603 | W30: 1126.1759 | X30: 1104.9337 | Y30: 1083.125 | Z30: 1059.1622 | AA30: 1032.9131 | AB30: 1010.4274 | AC30: 995.5354 | AD30: 982.41821 | AE30: 972.82416 | AF30: 963.53149 | AG30: 953.68817 | AH30: 944.03253 | AI30: 934.08258 | AJ30: 923.65735 | AK30: 913.49579 | AL30: 902.88867 | AM30: 892.90234 | AN30: 883.89471 | AO30: 874.63379 | AP30: 865.38116
A31: Solar Photovoltaic with Storage | E31: 0 | F31: 0 | G31: 0 | H31: 0 | I31: 0 | J31: 0 | K31: 0 | L31: 0 | M31: 0 | N31: 0 | O31: 0 | P31: 0 | Q31: 1990.2426 | R31: 1815.7078 | S31: 1727.0636 | T31: 1664.7429 | U31: 1636.3778 | V31: 1613.1074 | W31: 1583.3934 | X31: 1554.3307 | Y31: 1525.6029 | Z31: 1493.6288 | AA31: 1459.749 | AB31: 1429.7605 | AC31: 1408.1046 | AD31: 1388.4769 | AE31: 1372.9846 | AF31: 1358.053 | AG31: 1342.3086 | AH31: 1324.3932 | AI31: 1306.6277 | AJ31: 1288.8008 | AK31: 1272.3455 | AL31: 1255.7124 | AM31: 1240.2476 | AN31: 1226.1519 | AO31: 1211.8246 | AP31: 1197.4194
A32: Wind | E32: 0 | F32: 0 | G32: 0 | H32: 0 | I32: 0 | J32: 0 | K32: 0 | L32: 0 | M32: 0 | N32: 0 | O32: 0 | P32: 0 | Q32: 1403.4432 | R32: 1373.5674 | S32: 1355.3876 | T32: 1335.6964 | U32: 1323.0836 | V32: 1314.7931 | W32: 1310.4572 | X32: 1305.5303 | Y32: 1299.4591 | Z32: 1291.8689 | AA32: 1282.1929 | AB32: 1274.0302 | AC32: 1268.3687 | AD32: 1263.1692 | AE32: 1257.3906 | AF32: 1251.9689 | AG32: 1246.483 | AH32: 1240.9148 | AI32: 1234.5249 | AJ32: 1227.4606 | AK32: 1220.6971 | AL32: 1213.287 | AM32: 1206.6594 | AN32: 1201.3143 | AO32: 1196.0582 | AP32: 1190.3685
A33: Offshore Wind | E33: 0 | F33: 0 | G33: 0 | H33: 0 | I33: 0 | J33: 0 | K33: 0 | L33: 0 | M33: 0 | N33: 0 | O33: 0 | P33: 0 | Q33: 3505.9392 | R33: 3421.3228 | S33: 3255.593 | T33: 3113.0251 | U33: 3031.7678 | V33: 2962.2402 | W33: 2909.4814 | X33: 2863.9941 | Y33: 2824.739 | Z33: 2793.4255 | AA33: 2758.707 | AB33: 2728.2498 | AC33: 2705.8147 | AD33: 2684.4131 | AE33: 2661.8296 | AF33: 2640.0525 | AG33: 2618.1892 | AH33: 2596.2034 | AI33: 2572.5574 | AJ33: 2547.5757 | AK33: 2523.2944 | AL33: 2497.7542 | AM33: 2473.9021 | AN33: 2452.7397 | AO33: 2431.8081 | AP33: 2410.0474
A34: Diurnal Storage | E34: 0 | F34: 0 | G34: 0 | H34: 0 | I34: 0 | J34: 0 | K34: 0 | L34: 0 | M34: 0 | N34: 0 | O34: 0 | P34: 0 | Q34: 1579.6364 | R34: 1373.427 | S34: 1261.5312 | T34: 1215.0668 | U34: 1192.2332 | V34: 1174.9497 | W34: 1161.2566 | X34: 1141.6066 | Y34: 1124.7533 | Z34: 1104.9736 | AA34: 1086.9188 | AB34: 1068.4462 | AC34: 1050.7478 | AD34: 1033.489 | AE34: 1017.5148 | AF34: 1002.2786 | AG34: 986.32526 | AH34: 962.95099 | AI34: 941.0545 | AJ34: 920.56812 | AK34: 903.48627 | AL34: 887.34985 | AM34: 872.77679 | AN34: 859.18884 | AO34: 845.71124 | AP34: 831.97687
A35: Distributed Generation
A36: Base | E36: 0 | F36: 0 | G36: 0 | H36: 0 | I36: 0 | J36: 0 | K36: 0 | L36: 0 | M36: 0 | N36: 0 | O36: 0 | P36: 0 | Q36: 1742.6521 | R36: 1702.2501 | S36: 1676.4463 | T36: 1648.8514 | U36: 1630.061 | V36: 1616.6338 | W36: 1608.0876 | X36: 1598.8265 | Y36: 1588.1783 | Z36: 1575.6949 | AA36: 1560.6981 | AB36: 1547.575 | AC36: 1537.5122 | AD36: 1528.0243 | AE36: 1517.8508 | AF36: 1508.124 | AG36: 1498.3351 | AH36: 1488.4624 | AI36: 1477.6227 | AJ36: 1465.9974 | AK36: 1454.7548 | AL36: 1442.7654 | AM36: 1431.7305 | AN36: 1422.2358 | AO36: 1412.8619 | AP36: 1402.9918
A37: Peak | E37: 0 | F37: 0 | G37: 0 | H37: 0 | I37: 0 | J37: 0 | K37: 0 | L37: 0 | M37: 0 | N37: 0 | O37: 0 | P37: 0 | Q37: 2093.3884 | R37: 2044.855 | S37: 2013.8577 | T37: 1911.0734 | U37: 1801.8679 | V37: 1704.3579 | W37: 1616.9463 | X37: 1557.8895 | Y37: 1525.7257 | Z37: 1504.5897 | AA37: 1488.7253 | AB37: 1474.6638 | AC37: 1463.5291 | AD37: 1452.9486 | AE37: 1441.7239 | AF37: 1430.9309 | AG37: 1420.0863 | AH37: 1409.1704 | AI37: 1397.3477 | AJ37: 1384.7927 | AK37: 1372.6107 | AL37: 1359.736 | AM37: 1347.7726 | AN37: 1337.2687 | AO37: 1326.8856 | AP37: 1316.0447
C39: Cofire Cost Adder: | D39: 280 | E39: 2011$/kW | G39: =D39*$E$66 -> 318.17095 | H39: 2018$/kW
C40: Scrubber Cost Adder: | D40: 520 | E40: 2011$/kW | G40: =D40*$E$66 -> 590.8889 | H40: 2018$/kW
D43: Material Price Index: | E43: 1 | F43: 1 | G43: 1 | H43: 1 | I43: 1 | J43: 1 | K43: 1 | L43: 1 | M43: 1 | N43: 1 | O43: 1 | P43: 0.940434 | Q43: 0.922192 | R43: 0.911746 | S43: 0.900241 | T43: 0.893472 | U43: 0.889601 | V43: 0.888396 | W43: 0.886784 | X43: 0.884387 | Y43: 0.880946 | Z43: 0.876065 | AA43: 0.872201 | AB43: 0.870038 | AC43: 0.868184 | AD43: 0.865924 | AE43: 0.8639 | AF43: 0.861825 | AG43: 0.859684 | AH43: 0.856964 | AI43: 0.853765 | AJ43: 0.850762 | AK43: 0.847295 | AL43: 0.844362 | AM43: 0.842317 | AN43: 0.840326 | AO43: 0.838021 | AP43: 0.838021
A44: Technology | B44: 2010 | C44: 2011 | D44: 2012 | E44: 2013 | F44: 2014 | G44: 2015 | H44: 2016 | I44: 2017 | J44: 2018 | K44: 2019 | L44: 2020 | M44: 2021 | N44: 2022 | O44: 2023 | P44: 2024 | Q44: 2025 | R44: 2026 | S44: 2027 | T44: 2028 | U44: 2029 | V44: 2030 | W44: 2031 | X44: 2032 | Y44: 2033 | Z44: 2034 | AA44: 2035 | AB44: 2036 | AC44: 2037 | AD44: 2038 | AE44: 2039 | AF44: 2040 | AG44: 2041 | AH44: 2042 | AI44: 2043 | AJ44: 2044 | AK44: 2045 | AL44: 2046 | AM44: 2047 | AN44: 2048 | AO44: 2049 | AP44: 2050
A45: Hydro | Q45: =Q26/Q43 -> 3350.2063 | R45: =R26/R43 -> 3316.4553 | S45: =S26/S43 -> 3314.3837 | T45: =T26/T43 -> 3290.9764 | U45: =U26/U43 -> 3274.0859 | V45: =V26/V43 -> 3257.9831 | W45: =W26/W43 -> 3253.1419 | X45: =X26/X43 -> 3249.6953 | ... AP45: =AP26/AP43 -> 1969.4827
A46: Gas-CT | Q46: =AVERAGE(Q18:Q19)/Q43 -> 1253.86 | R46: =AVERAGE(R18:R19)/R43 -> 1238.6923 | S46: =AVERAGE(S18:S19)/S43 -> 1226.5978 | T46: =AVERAGE(T18:T19)/T43 -> 1203.9206 | U46: =AVERAGE(U18:U19)/U43 -> 1185.0378 | V46: =AVERAGE(V18:V19)/V43 -> 1169.487 | W46: =AVERAGE(W18:W19)/W43 -> 1157.2622 | X46: =AVERAGE(X18:X19)/X43 -> 1146.5992 | ... AP46: =AVERAGE(AP18:AP19)/AP43 -> 1038.0741
A47: Gas-CC | Q47: =AVERAGE(Q14:Q15)/Q43 -> 921.1708 | R47: =AVERAGE(R14:R15)/R43 -> 910.96216 | S47: =AVERAGE(S14:S15)/S43 -> 906.5767 | T47: =AVERAGE(T14:T15)/T43 -> 895.56078 | U47: =AVERAGE(U14:U15)/U43 -> 886.64676 | V47: =AVERAGE(V14:V15)/V43 -> 878.8435 | W47: =AVERAGE(W14:W15)/W43 -> 873.8331 | X47: =AVERAGE(X14:X15)/X43 -> 869.6111 | ... AP47: =AVERAGE(AP14:AP15)/AP43 -> 813.6907
...

Sheet O&M, Heat Rates
A1: Technology | C1: Variable O&M | D1: Fixed O&M | E1: Heat Rate 2016 | F1: Heat Rate nth | G1: HR Slope
A2: Hydro | C2: 1.4 | D2: 42.01 | E2: 0 | F2: 0 | G2: =(E2-F2)/($G$25-$G$24) -> 0
A3: Gas-CT | C3: =AVERAGE(4.72,4.52) -> 4.62 | D3: =AVERAGE(16.38,7.04) -> 11.71 | E3: =AVERAGE(9124,9905) -> 9514.5 | F3: =E3 -> 9514.5 | G3: =(E3-F3)/($G$25-$G$24) -> 0 | J3: Table from: https://www.eia.gov/outlooks/aeo/assumptions/pdf/table_8.2.pdf
A4: Gas-CC | C4: =AVERAGE(2.56,1.88) -> 2.22 | D4: =AVERAGE(14.17,12.26) -> 13.215 | E4: =AVERAGE(6431,6370) -> 6400.5 | F4: =E4 -> 6400.5 | G4: =(E4-F4)/($G$25-$G$24) -> 0 | J4: For AEO 2023 from: https://www.eia.gov/outlooks/aeo/assumptions/pdf/EMM_Assumptions.pdf
A5: Gas-CC-CCS | C5: 5.87 | D5: 27.74 | E5: 7124 | F5: =E5 -> 7124 | G5: =(E5-F5)/($G$25-$G$24) -> 0
A6: CoalOldScr | C6: NA | D6: NA | E6: NA | F6: NA
A7: CoalOldUns | C7: NA | D7: NA | E7: NA | F7: NA
A8: Coal-new | C8: 4.52 | D8: 40.79 | E8: 8638 | F8: 8638 | G8: =(E8-F8)/($G$25-$G$24) -> 0
A9: Coal-IGCC | C9: 8.0225267 | D9: =57079.9443618202/1000 -> 57.079944 | E9: 8700 | F9: 7450 | G9: =(E9-F9)/($G$25-$G$24) -> 113.63636
A10: coal-CCS | C10: 11.03 | D10: 59.85 | E10: 12507 | F10: 12507 | G10: =(E10-F10)/($G$25-$G$24) -> 0
A11: Partial Coal CCS | C11: 7.11 | D11: 54.57 | E11: 9751 | F11: =E11 -> 9751
A12: o-g-s | C12: NA | D12: NA | E12: NA | F12: NA
A13: Nuclear | C13: 2.38 | D13: 122.26 | E13: 10455 | F13: =E13 -> 10455 | G13: =(E13-F13)/($G$25-$G$24) -> 0
A14: Nuclear SMR | C14: 3.02 | D14: 95.48 | E14: 10455 | F14: =E14 -> 10455 | G14: =(E14-F14)/($G$25-$G$24) -> 0
A15: geothermal | C15: 1.17 | D15: 137.5 | E15: 0 | F15: 0 | G15: =(E15-F15)/($G$25-$G$24) -> 0
A16: biopower | C16: 4.85 | D16: 126.36 | E16: 13500 | F16: 13500 | G16: =(E16-F16)/($G$25-$G$24) -> 0
A17: CofireOld | C17: NA | D17: NA | E17: NA | F17: NA
A18: CofireNew | C18: =C8 -> 4.52 | D18: =D8 -> 40.79 | E18: NA | F18: NA
A19: lfill-gas | C19: 6.23 | D19: 20.2 | E19: 8513 | F19: 8513 | G19: =(E19-F19)/($G$25-$G$24) -> 0
A20: Ocean | C20: NA | D20: NA | E20: NA | F20: NA
A21: Others | C21: 0 | D21: 24.68 | E21: 9271 | F21: 9271 | G21: =(E21-F21)/($G$25-$G$24) -> 0
A23: Geothermal Overnight Capital Costs
A24: =B15 -> 0 | F24: Cur Year | G24: 2019
F25: nth year | G25: 2030
E31: Partial CCS
D32: 2015 | E32: 9750
D33: 2016 | E33: 9750
D34: 2017 | E34: 9750
D35: 2018 | E35: =E34-($E$34-$E$47)/13 -> 9709.3077
D36: 2019 | E36: =E35-($E$34-$E$47)/13 -> 9668.6154
D37: 2020 | E37: =E36-($E$34-$E$47)/13 -> 9627.9231
D38: 2021 | E38: =E37-($E$34-$E$47)/13 -> 9587.2308
D39: 2022 | E39: =E38-($E$34-$E$47)/13 -> 9546.5385
D40: 2023 | E40: =E39-($E$34-$E$47)/13 -> 9505.8462 | N40: FOM
D41: 2024 | E41: =E40-($E$34-$E$47)/13 -> 9465.1538 | K41: Biomass | L41: 141.5 | M41: =L41*1.2/1.08 -> 157.22222 | N41: =ROUND(M41,2) -> 157.22
D42: 2025 | E42: =E41-($E$34-$E$47)/13 -> 9424.4615 | K42: Nuclear | L42: 136.91 | M42: =L42*1.2/1.08 -> 152.12222 | N42: =ROUND(M42,2) -> 152.12
D43: 2026 | E43: =E42-($E$34-$E$47)/13 -> 9383.7692 | K43: SMR | L43: 106.92 | M43: =L43*1.2/1.08 -> 118.8 | N43: =ROUND(M43,2) -> 118.8
D44: 2027 | E44: =E43-($E$34-$E$47)/13 -> 9343.0769
D45: 2028 | E45: =E44-($E$34-$E$47)/13 -> 9302.3846 | N45: VOM
D46: 2029 | E46: =E45-($E$34-$E$47)/13 -> 9261.6923 | K46: Biomass | L46: 5.44 | M46: =L46/1.08 -> 5.037037 | N46: =ROUND(M46,2) -> 5.04
...
