Workbook
Name IQ_CH: 110000
Name IQ_CQ: 5000
Name IQ_CY: 10000
Name IQ_DAILY: 500000
Name IQ_FH: 100000
Name IQ_FQ: 500
Name IQ_FY: 1000
Name IQ_LTM: 2000
Name IQ_MONTH: 15000
Name IQ_NTM: 6000
Name IQ_WEEK: 50000
Name IQ_YTD: 3000

Sheet Adding DGPV to Demand
A1: Reference Scenario
A3: AEO 2025 Demand (Quads)
A4: Demand is in Quads | C4: 2010 | D4: 2011 | E4: 2012 | F4: 2013 | G4: 2014 | H4: 2015 | I4: 2016 | J4: 2017 | K4: 2018 | L4: 2019 | M4: 2020 | N4: 2021 | O4: 2022 | P4: 2023 | Q4: 2024 | R4: 2025 | S4: 2026 | T4: 2027 | U4: 2028 | V4: 2029 | W4: 2030 | X4: 2031 | Y4: 2032 | Z4: 2033 | AA4: 2034 | AB4: 2035 | AC4: 2036 | AD4: 2037 | AE4: 2038 | AF4: 2039 | AG4: 2040 | AH4: 2041 | AI4: 2042 | AJ4: 2043 | AK4: 2044 | AL4: 2045 | AM4: 2046 | AN4: 2047 | AO4: 2048 | AP4: 2049 | AQ4: 2050
A5: Reference Case | B5: New England | C5: 0.42 | D5: 0.411741 | E5: 0.410174 | F5: 0.409348 | G5: 0.43727 | H5: 0.405484 | I5: 0.398208 | J5: 0.419095 | K5: 0.41218 | L5: 0.387309 | M5: 0.381028 | N5: 0.384754 | O5: 0.387155 | P5: 0.377497 | Q5: 0.381749 | R5: 0.378134 | S5: 0.37652 | T5: 0.382755 | U5: 0.388901 | V5: 0.396284 | W5: 0.402134 | X5: 0.408362 | Y5: 0.414834 | Z5: 0.4212 | AA5: 0.427768 | AB5: 0.436025 | AC5: 0.445403 | AD5: 0.454359 | AE5: 0.46358 | AF5: 0.472958 | AG5: 0.481784 | AH5: 0.489998 | AI5: 0.497335 | AJ5: 0.504099 | AK5: 0.510189 | AL5: 0.516861 | AM5: 0.521473 | AN5: 0.526558 | AO5: 0.531247 | AP5: 0.536503 | AQ5: 0.542338
A6: Reference Case | B6: Middle Atlantic | C6: 1.27 | D6: 1.259176 | E6: 1.237963 | F6: 1.232784 | G6: 1.261565 | H6: 1.257234 | I6: 1.247386 | J6: 1.221935 | K6: 1.257952 | L6: 1.237597 | M6: 1.180221 | N6: 1.219447 | O6: 1.240986 | P6: 1.217156 | Q6: 1.21804 | R6: 1.2345 | S6: 1.239468 | T6: 1.256736 | U6: 1.270451 | V6: 1.288511 | W6: 1.305051 | X6: 1.321339 | Y6: 1.344669 | Z6: 1.365929 | AA6: 1.391992 | AB6: 1.419689 | AC6: 1.45093 | AD6: 1.479173 | AE6: 1.508404 | AF6: 1.538909 | AG6: 1.567551 | AH6: 1.593385 | AI6: 1.615654 | AJ6: 1.636443 | AK6: 1.655608 | AL6: 1.675578 | AM6: 1.694594 | AN6: 1.714836 | AO6: 1.734916 | AP6: 1.754872 | AQ6: 1.77657
A7: Reference Case | B7: East North Central | C7: 1.97 | D7: 1.969802 | E7: 1.961978 | F7: 1.929469 | G7: 1.945087 | H7: 1.901925 | I7: 1.903118 | J7: 1.873526 | K7: 1.937452 | L7: 1.882005 | M7: 1.840859 | N7: 1.892778 | O7: 1.88735 | P7: 1.87929 | Q7: 1.890297 | R7: 1.931995 | S7: 1.946298 | T7: 1.966078 | U7: 1.982243 | V7: 1.999956 | W7: 2.018254 | X7: 2.038038 | Y7: 2.071262 | Z7: 2.103052 | AA7: 2.145368 | AB7: 2.189698 | AC7: 2.234562 | AD7: 2.274203 | AE7: 2.314279 | AF7: 2.355029 | AG7: 2.395181 | AH7: 2.431485 | AI7: 2.465456 | AJ7: 2.496764 | AK7: 2.52574 | AL7: 2.552003 | AM7: 2.578634 | AN7: 2.607156 | AO7: 2.634363 | AP7: 2.66136 | AQ7: 2.688507
A8: Reference Case | B8: West North Central | C8: 1.003 | D8: 1.004251 | E8: 1.002292 | F8: 1.002219 | G8: 1.034027 | H8: 1.01352 | I8: 1.008327 | J8: 1.001618 | K8: 1.036193 | L8: 1.024919 | M8: 0.996421 | N8: 1.042554 | O8: 1.063648 | P8: 1.05566 | Q8: 1.095113 | R8: 1.114588 | S8: 1.102387 | T8: 1.108819 | U8: 1.113754 | V8: 1.123848 | W8: 1.134889 | X8: 1.147373 | Y8: 1.165714 | Z8: 1.185565 | AA8: 1.211766 | AB8: 1.239657 | AC8: 1.266266 | AD8: 1.290929 | AE8: 1.315301 | AF8: 1.338705 | AG8: 1.361342 | AH8: 1.382941 | AI8: 1.404533 | AJ8: 1.424942 | AK8: 1.443783 | AL8: 1.460188 | AM8: 1.477045 | AN8: 1.495429 | AO8: 1.514562 | AP8: 1.534466 | AQ8: 1.554376
A9: Reference Case | B9: South Atlantic | C9: 2.815 | D9: 2.732388 | E9: 2.663072 | F9: 2.674564 | G9: 2.72141 | H9: 2.715687 | I9: 2.724914 | J9: 2.672496 | K9: 2.774264 | L9: 2.776458 | M9: 2.691128 | N9: 2.806581 | O9: 2.888761 | P9: 2.878955 | Q9: 2.944336 | R9: 2.971613 | S9: 2.985176 | T9: 3.019987 | U9: 3.0479 | V9: 3.087952 | W9: 3.125311 | X9: 3.163777 | Y9: 3.211586 | Z9: 3.258795 | AA9: 3.309393 | AB9: 3.363539 | AC9: 3.42513 | AD9: 3.489539 | AE9: 3.554402 | AF9: 3.621217 | AG9: 3.684103 | AH9: 3.741977 | AI9: 3.795249 | AJ9: 3.845744 | AK9: 3.891114 | AL9: 3.933096 | AM9: 3.973318 | AN9: 4.016439 | AO9: 4.063365 | AP9: 4.113973 | AQ9: 4.169602
A10: Reference Case | B10: East South Central | C10: 1.152 | D10: 1.121258 | E10: 1.091933 | F10: 1.119487 | G10: 1.0895 | H10: 1.048215 | I10: 1.037194 | J10: 1.00516 | K10: 1.058618 | L10: 1.052048 | M10: 1.000733 | N10: 1.045416 | O10: 1.062294 | P10: 1.061352 | Q10: 1.061449 | R10: 1.06264 | S10: 1.084461 | T10: 1.097089 | U10: 1.107544 | V10: 1.11454 | W10: 1.12145 | X10: 1.130001 | Y10: 1.141503 | Z10: 1.153738 | AA10: 1.169826 | AB10: 1.185598 | AC10: 1.200375 | AD10: 1.217726 | AE10: 1.235288 | AF10: 1.253465 | AG10: 1.269736 | AH10: 1.285398 | AI10: 1.299866 | AJ10: 1.312407 | AK10: 1.322835 | AL10: 1.332618 | AM10: 1.341577 | AN10: 1.351043 | AO10: 1.36318 | AP10: 1.376873 | AQ10: 1.391533
A11: Reference Case | B11: West South Central | C11: 1.875 | D11: 1.945614 | E11: 1.898577 | F11: 1.909073 | G11: 2.028996 | H11: 2.043592 | I11: 2.027452 | J11: 2.020951 | K11: 2.118778 | L11: 2.156085 | M11: 2.069257 | N11: 2.19944 | O11: 2.292464 | P11: 2.241604 | Q11: 2.354884 | R11: 2.411411 | S11: 2.43222 | T11: 2.457628 | U11: 2.479679 | V11: 2.504043 | W11: 2.528003 | X11: 2.552916 | Y11: 2.592839 | Z11: 2.636189 | AA11: 2.686275 | AB11: 2.742114 | AC11: 2.804967 | AD11: 2.871648 | AE11: 2.927629 | AF11: 2.981654 | AG11: 3.028419 | AH11: 3.071063 | AI11: 3.11248 | AJ11: 3.153837 | AK11: 3.189507 | AL11: 3.225005 | AM11: 3.254956 | AN11: 3.285466 | AO11: 3.321059 | AP11: 3.360311 | AQ11: 3.404515
A12: Reference Case | B12: Mountain | C12: 0.898 | D12: 0.916749 | E12: 0.926038 | F12: 0.919709 | G12: 0.919469 | H12: 0.922001 | I12: 0.930779 | J12: 0.942087 | K12: 0.950759 | L12: 0.946925 | M12: 0.954759 | N12: 0.994862 | O12: 1.013368 | P12: 1.001265 | Q12: 1.059129 | R12: 1.065198 | S12: 1.074049 | T12: 1.090856 | U12: 1.107022 | V12: 1.129262 | W12: 1.153286 | X12: 1.180213 | Y12: 1.213107 | Z12: 1.249836 | AA12: 1.292087 | AB12: 1.33559 | AC12: 1.377219 | AD12: 1.416983 | AE12: 1.456454 | AF12: 1.494817 | AG12: 1.533247 | AH12: 1.57138 | AI12: 1.606998 | AJ12: 1.640574 | AK12: 1.672926 | AL12: 1.704548 | AM12: 1.736956 | AN12: 1.76903 | AO12: 1.801999 | AP12: 1.834661 | AQ12: 1.867863
A13: Reference Case | B13: Pacific | C13: 1.403 | D13: 1.429711 | E13: 1.415364 | F13: 1.398721 | G13: 1.407587 | H13: 1.405649 | I13: 1.39239 | J13: 1.416317 | K13: 1.405308 | L13: 1.374199 | M13: 1.376155 | N13: 1.390702 | O13: 1.423533 | P13: 1.393828 | Q13: 1.426468 | R13: 1.406646 | S13: 1.41243 | T13: 1.444237 | U13: 1.47231 | V13: 1.500187 | W13: 1.528918 | X13: 1.556167 | Y13: 1.595039 | Z13: 1.63897 | AA13: 1.688788 | AB13: 1.74043 | AC13: 1.789119 | AD13: 1.835435 | AE13: 1.881716 | AF13: 1.928023 | AG13: 1.973098 | AH13: 2.015455 | AI13: 2.054493 | AJ13: 2.088835 | AK13: 2.121535 | AL13: 2.15438 | AM13: 2.187462 | AN13: 2.220138 | AO13: 2.252499 | AP13: 2.285044 | AQ13: 2.316653
A14: Reference Case | B14: Total | C14: 12.81 | D14: 12.79069 | E14: 12.607393 | F14: 12.595371 | G14: 12.844912 | H14: 12.713305 | I14: 12.669767 | J14: 12.573186 | K14: 12.951503 | L14: 12.837544 | M14: 12.490561 | N14: 12.976532 | O14: 13.25956 | P14: 13.106607 | Q14: 13.431463 | R14: 13.576725 | S14: 13.653009 | T14: 13.824183 | U14: 13.969803 | V14: 14.144584 | W14: 14.317296 | X14: 14.498184 | Y14: 14.750555 | Z14: 15.013274 | AA14: 15.323262 | AB14: 15.652338 | AC14: 15.993971 | AD14: 16.329994 | AE14: 16.657051 | AF14: 16.984776 | AG14: 17.294462 | AH14: 17.58308 | AI14: 17.852062 | AJ14: 18.103643 | AK14: 18.333237 | AL14: 18.554274 | AM14: 18.766016 | AN14: 18.986097 | AO14: 19.217192 | AP14: 19.458061 | AQ14: 19.711958
A16: AEO 2025 Demand met by Rooftop PV (Quads)
B17: Demand Adjusted | C17: 2010 | D17: 2011 | E17: 2012 | F17: 2013 | G17: 2014 | H17: 2015 | I17: 2016 | J17: 2017 | K17: 2018 | L17: 2019 | M17: 2020 | N17: 2021 | O17: 2022 | P17: 2023 | Q17: 2024 | R17: 2025 | S17: 2026 | T17: 2027 | U17: 2028 | V17: 2029 | W17: 2030 | X17: 2031 | Y17: 2032 | Z17: 2033 | AA17: 2034 | AB17: 2035 | AC17: 2036 | AD17: 2037 | AE17: 2038 | AF17: 2039 | AG17: 2040 | AH17: 2041 | AI17: 2042 | AJ17: 2043 | AK17: 2044 | AL17: 2045 | AM17: 2046 | AN17: 2047 | AO17: 2048 | AP17: 2049 | AQ17: 2050
B18: New England | F18: 0.00167267 | G18: 0.00278517 | H18: 0.00578068 | I18: 0.00872679 | J18: 0.01195686 | K18: 0.0139822 | L18: 0.01629253 | M18: 0.01992428 | N18: 0.02359684 | O18: 0.02736841 | P18: 0.03099253 | Q18: 0.0357422 | R18: 0.04032379 | S18: 0.0448264 | T18: 0.04760179 | U18: 0.04963547 | V18: 0.05154344 | W18: 0.05391487 | X18: 0.0562153 | Y18: 0.05894352 | Z18: 0.06182887 | AA18: 0.06483197 | AB18: 0.06685013 | AC18: 0.06867847 | AD18: 0.07077548 | AE18: 0.07267346 | AF18: 0.07437146 | AG18: 0.0761626 | AH18: 0.07800837 | AI18: 0.07996552 | AJ18: 0.08174554 | AK18: 0.08372449 | AL18: 0.08534346 | AM18: 0.08798128 | AN18: 0.09014553 | AO18: 0.09253875 | AP18: 0.09468364 | AQ18: 0.09650975
B19: Middle Atlantic | F19: 0.0052621 | G19: 0.00596437 | H19: 0.00962381 | I19: 0.01225282 | J19: 0.01504372 | K19: 0.01806602 | L19: 0.02173509 | M19: 0.02453379 | N19: 0.02881565 | O19: 0.03457393 | P19: 0.04023016 | Q19: 0.04562122 | R19: 0.05078501 | S19: 0.05586857 | T19: 0.05893421 | U19: 0.06262864 | V19: 0.06542582 | W19: 0.06899412 | X19: 0.07325165 | Y19: 0.07616265 | Z19: 0.08069563 | AA19: 0.08399559 | AB19: 0.0869897 | AC19: 0.08891279 | AD19: 0.09196583 | AE19: 0.09431276 | AF19: 0.09583302 | AG19: 0.09793337 | AH19: 0.10050705 | AI19: 0.10357404 | AJ19: 0.10644192 | AK19: 0.10950158 | AL19: 0.11204503 | AM19: 0.11486118 | AN19: 0.11747842 | AO19: 0.12050196 | AP19: 0.12355863 | AQ19: 0.12574277
B20: East North Central | F20: 0.00036836 | G20: 0.00046887 | H20: 0.00072127 | I20: 0.00087959 | J20: 0.00118232 | K20: 0.00169836 | L20: 0.00269954 | M20: 0.00484263 | N20: 0.00693252 | O20: 0.00877192 | P20: 0.01124545 | Q20: 0.01302954 | R20: 0.01478328 | S20: 0.01652646 | T20: 0.01773086 | U20: 0.01949677 | V20: 0.0220152 | W20: 0.02447892 | X20: 0.02808832 | Y20: 0.02975622 | Z20: 0.03300164 | AA20: 0.03468452 | AB20: 0.03580428 | AC20: 0.03670269 | AD20: 0.03870319 | AE20: 0.03994628 | AF20: 0.04091229 | AG20: 0.04208515 | AH20: 0.04367264 | AI20: 0.04552074 | AJ20: 0.04727099 | AK20: 0.04917426 | AL20: 0.05132433 | AM20: 0.0533068 | AN20: 0.05472922 | AO20: 0.05689391 | AP20: 0.05895755 | AQ20: 0.06077704
B21: West North Central | F21: 0.00018508 | G21: 0.00044961 | H21: 0.00094157 | I21: 0.00142286 | J21: 0.00301469 | K21: 0.00475015 | L21: 0.00618115 | M21: 0.00703413 | N21: 0.00791695 | O21: 0.00906202 | P21: 0.01040362 | Q21: 0.01188427 | R21: 0.01327661 | S21: 0.01465661 | T21: 0.01546824 | U21: 0.01671304 | V21: 0.01799119 | W21: 0.01972297 | X21: 0.02182063 | Y21: 0.02361919 | Z21: 0.02536194 | AA21: 0.02613925 | AB21: 0.02663607 | AC21: 0.02735086 | AD21: 0.02810893 | AE21: 0.02881864 | AF21: 0.02973082 | AG21: 0.03073557 | AH21: 0.03177758 | AI21: 0.03270853 | AJ21: 0.03370287 | AK21: 0.03501664 | AL21: 0.03693784 | AM21: 0.03838454 | AN21: 0.03950594 | AO21: 0.04058049 | AP21: 0.04160092 | AQ21: 0.04261882
B22: South Atlantic | F22: 0.00133256 | G22: 0.0016204 | H22: 0.00351441 | I22: 0.00552347 | J22: 0.00760007 | K22: 0.00951109 | L22: 0.01213289 | M22: 0.01558821 | N22: 0.01952075 | O22: 0.02551028 | P22: 0.0313469 | Q22: 0.03641087 | R22: 0.04195903 | S22: 0.04780483 | T22: 0.05310735 | U22: 0.05943716 | V22: 0.06579823 | W22: 0.07277868 | X22: 0.08076659 | Y22: 0.08906062 | Z22: 0.09860785 | AA22: 0.10787094 | AB22: 0.11533953 | AC22: 0.122362 | AD22: 0.12988052 | AE22: 0.13713713 | AF22: 0.14428676 | AG22: 0.15246633 | AH22: 0.16139361 | AI22: 0.17076042 | AJ22: 0.18036578 | AK22: 0.19074592 | AL22: 0.20168803 | AM22: 0.21265143 | AN22: 0.22375144 | AO22: 0.23503706 | AP22: 0.24636291 | AQ22: 0.25751464
B23: East South Central | F23: 0.00023748 | G23: 0.00025254 | H23: 0.00035332 | I23: 0.00040601 | J23: 0.00051035 | K23: 0.0006367 | L23: 0.00071555 | M23: 0.00074224 | N23: 0.00080511 | O23: 0.00090031 | P23: 0.00099188 | Q23: 0.00144273 | R23: 0.00194622 | S23: 0.00249134 | T23: 0.00301383 | U23: 0.00373577 | V23: 0.00525406 | W23: 0.00667943 | X23: 0.00820828 | Y23: 0.01042327 | Z23: 0.0126605 | AA23: 0.0142036 | AB23: 0.01607609 | AC23: 0.01853393 | AD23: 0.01965464 | AE23: 0.02063287 | AF23: 0.02146668 | AG23: 0.02275986 | AH23: 0.02392245 | AI23: 0.025364 | AJ23: 0.02730623 | AK23: 0.02936357 | AL23: 0.03135868 | AM23: 0.03347496 | AN23: 0.03570308 | AO23: 0.03718398 | AP23: 0.03857136 | AQ23: 0.04007391
B24: West South Central | F24: 0.00014235 | G24: 0.0002382 | H24: 0.00103263 | I24: 0.0016752 | J24: 0.00229294 | K24: 0.00351775 | L24: 0.00449508 | M24: 0.00625313 | N24: 0.00849031 | O24: 0.01247019 | P24: 0.01568606 | Q24: 0.01858685 | R24: 0.021735 | S24: 0.02512675 | T24: 0.0284272 | U24: 0.03214111 | V24: 0.03680368 | W24: 0.04168142 | X24: 0.04718087 | Y24: 0.05204572 | Z24: 0.05771753 | AA24: 0.06286073 | AB24: 0.06680741 | AC24: 0.07103123 | AD24: 0.07521442 | AE24: 0.0796975 | AF24: 0.0841641 | AG24: 0.08913631 | AH24: 0.09430926 | AI24: 0.09966528 | AJ24: 0.10505338 | AK24: 0.11044118 | AL24: 0.11604864 | AM24: 0.12220939 | AN24: 0.12825277 | AO24: 0.13409156 | AP24: 0.13984746 | AQ24: 0.14568087
B25: Mountain | F25: 0.00266936 | G25: 0.00326953 | H25: 0.00816188 | I25: 0.01081065 | J25: 0.01339974 | K25: 0.01631836 | L25: 0.01981938 | M25: 0.02503399 | N25: 0.02996682 | O25: 0.0353967 | P25: 0.04102251 | Q25: 0.04503927 | R25: 0.04928276 | S25: 0.0536132 | T25: 0.05706156 | U25: 0.06062244 | V25: 0.06481407 | W25: 0.06937532 | X25: 0.07392272 | Y25: 0.07940029 | Z25: 0.08462965 | AA25: 0.08946576 | AB25: 0.09370402 | AC25: 0.09798839 | AD25: 0.10256899 | AE25: 0.10726379 | AF25: 0.112204 | AG25: 0.11710796 | AH25: 0.12217586 | AI25: 0.1275849 | AJ25: 0.13307438 | AK25: 0.13843215 | AL25: 0.14398207 | AM25: 0.14968476 | AN25: 0.15578475 | AO25: 0.16187062 | AP25: 0.16800241 | AQ25: 0.17396012
B26: Pacific | F26: 0.00833691 | G26: 0.010179 | H26: 0.02845363 | I26: 0.03838903 | J26: 0.04755548 | K26: 0.05658236 | L26: 0.06582356 | M26: 0.07971136 | N26: 0.09132634 | O26: 0.10085138 | P26: 0.12388786 | Q26: 0.14586288 | R26: 0.16576168 | S26: 0.18524232 | T26: 0.19931312 | U26: 0.21207894 | V26: 0.22539939 | W26: 0.23995067 | X26: 0.2562223 | Y26: 0.2705057 | Z26: 0.2847367 | AA26: 0.29795061 | AB26: 0.30783631 | AC26: 0.31764085 | AD26: 0.32742764 | AE26: 0.33670873 | AF26: 0.34499118 | AG26: 0.35344186 | AH26: 0.36231908 | AI26: 0.37143154 | AJ26: 0.38114116 | AK26: 0.39027405 | AL26: 0.39879774 | AM26: 0.40782672 | AN26: 0.41694019 | AO26: 0.42613998 | AP26: 0.434677 | AQ26: 0.44392141
B27: Total | F27: 0.02020687 | G27: 0.02522769 | H27: 0.0585832 | I27: 0.08008642 | J27: 0.10255617 | K27: 0.12506299 | L27: 0.14989477 | M27: 0.18366376 | N27: 0.21737129 | O27: 0.25490514 | P27: 0.30580697 | Q27: 0.35361983 | R27: 0.39985338 | S27: 0.44615648 | T27: 0.48065816 | U27: 0.51648934 | V27: 0.55504508 | W27: 0.5975764 | X27: 0.64567666 | Y27: 0.68991718 | Z27: 0.73924031 | AA27: 0.78200297 | AB27: 0.81604354 | AC27: 0.84920121 | AD27: 0.88429964 | AE27: 0.91719116 | AF27: 0.94796031 | AG27: 0.98182901 | AH27: 1.0180859 | AI27: 1.056575 | AJ27: 1.0961022 | AK27: 1.1366738 | AL27: 1.1775258 | AM27: 1.2203811 | AN27: 1.2622913 | AO27: 1.3048383 | AP27: 1.3462619 | AQ27: 1.3867993
A30: Total Demand (Quads) <-- This is used in the Demand by Case on the next tab
A31: Demand is in Quads | C31: 2010 | D31: 2011 | E31: 2012 | F31: 2013 | G31: 2014 | H31: 2015 | I31: 2016 | J31: 2017 | K31: 2018 | L31: 2019 | M31: 2020 | N31: 2021 | O31: 2022 | P31: 2023 | Q31: 2024 | R31: 2025 | S31: 2026 | T31: 2027 | U31: 2028 | V31: 2029 | W31: 2030 | X31: 2031 | Y31: 2032 | Z31: 2033 | AA31: 2034 | AB31: 2035 | AC31: 2036 | AD31: 2037 | AE31: 2038 | AF31: 2039 | AG31: 2040 | AH31: 2041 | AI31: 2042 | AJ31: 2043 | AK31: 2044 | AL31: 2045 | AM31: 2046 | AN31: 2047 | AO31: 2048 | AP31: 2049 | AQ31: 2050
A32: Reference Case | B32: New England | C32: =C5+C18 -> 0.42 | D32: =D5+D18 -> 0.411741 | E32: =E5+E18 -> 0.410174 | F32: =F5+F18 -> 0.41102067 | G32: =G5+G18 -> 0.44005517 | H32: =H5+H18 -> 0.41126468 | I32: =I5+I18 -> 0.40693479 | J32: =J5+J18 -> 0.43105186 | ... AQ32: =AQ5+AQ18 -> 0.63884775
A33: Reference Case | B33: Middle Atlantic | C33: =C6+C19 -> 1.27 | D33: =D6+D19 -> 1.259176 | E33: =E6+E19 -> 1.237963 | F33: =F6+F19 -> 1.2380461 | G33: =G6+G19 -> 1.2675294 | H33: =H6+H19 -> 1.2668578 | I33: =I6+I19 -> 1.2596388 | J33: =J6+J19 -> 1.2369787 | ... AQ33: =AQ6+AQ19 -> 1.9023128
A34: Reference Case | B34: East North Central | C34: =C7+C20 -> 1.97 | D34: =D7+D20 -> 1.969802 | E34: =E7+E20 -> 1.961978 | F34: =F7+F20 -> 1.9298374 | G34: =G7+G20 -> 1.9455559 | H34: =H7+H20 -> 1.9026463 | I34: =I7+I20 -> 1.9039976 | J34: =J7+J20 -> 1.8747083 | ... AQ34: =AQ7+AQ20 -> 2.749284
A35: Reference Case | B35: West North Central | C35: =C8+C21 -> 1.003 | D35: =D8+D21 -> 1.004251 | E35: =E8+E21 -> 1.002292 | F35: =F8+F21 -> 1.0024041 | G35: =G8+G21 -> 1.0344766 | H35: =H8+H21 -> 1.0144616 | I35: =I8+I21 -> 1.0097499 | J35: =J8+J21 -> 1.0046327 | ... AQ35: =AQ8+AQ21 -> 1.5969948
A36: Reference Case | B36: South Atlantic | C36: =C9+C22 -> 2.815 | D36: =D9+D22 -> 2.732388 | E36: =E9+E22 -> 2.663072 | F36: =F9+F22 -> 2.6758966 | G36: =G9+G22 -> 2.7230304 | H36: =H9+H22 -> 2.7192014 | I36: =I9+I22 -> 2.7304375 | J36: =J9+J22 -> 2.6800961 | ... AQ36: =AQ9+AQ22 -> 4.4271166
A37: Reference Case | B37: East South Central | C37: =C10+C23 -> 1.152 | D37: =D10+D23 -> 1.121258 | E37: =E10+E23 -> 1.091933 | F37: =F10+F23 -> 1.1197245 | G37: =G10+G23 -> 1.0897525 | H37: =H10+H23 -> 1.0485683 | I37: =I10+I23 -> 1.0376 | J37: =J10+J23 -> 1.0056704 | ... AQ37: =AQ10+AQ23 -> 1.4316069
A38: Reference Case | B38: West South Central | C38: =C11+C24 -> 1.875 | D38: =D11+D24 -> 1.945614 | E38: =E11+E24 -> 1.898577 | F38: =F11+F24 -> 1.9092153 | G38: =G11+G24 -> 2.0292342 | H38: =H11+H24 -> 2.0446246 | I38: =I11+I24 -> 2.0291272 | J38: =J11+J24 -> 2.0232439 | ... AQ38: =AQ11+AQ24 -> 3.5501959
A39: Reference Case | B39: Mountain | C39: =C12+C25 -> 0.898 | D39: =D12+D25 -> 0.916749 | E39: =E12+E25 -> 0.926038 | F39: =F12+F25 -> 0.92237836 | G39: =G12+G25 -> 0.92273853 | H39: =H12+H25 -> 0.93016288 | I39: =I12+I25 -> 0.94158965 | J39: =J12+J25 -> 0.95548674 | ... AQ39: =AQ12+AQ25 -> 2.0418231
A40: Reference Case | B40: Pacific | C40: =C13+C26 -> 1.403 | D40: =D13+D26 -> 1.429711 | E40: =E13+E26 -> 1.415364 | F40: =F13+F26 -> 1.4070579 | G40: =G13+G26 -> 1.417766 | H40: =H13+H26 -> 1.4341026 | I40: =I13+I26 -> 1.430779 | J40: =J13+J26 -> 1.4638725 | ... AQ40: =AQ13+AQ26 -> 2.7605744
A41: Reference Case | B41: Total | C41: =C14+C27 -> 12.81 | D41: =D14+D27 -> 12.79069 | E41: =E14+E27 -> 12.607393 | F41: =F14+F27 -> 12.615578 | G41: =G14+G27 -> 12.87014 | H41: =H14+H27 -> 12.771888 | I41: =I14+I27 -> 12.749853 | J41: =J14+J27 -> 12.675742 | ... AQ41: =AQ14+AQ27 -> 21.098757
A46: High Economic Growth
A48: AEO 2025 | B48: High Economic Gowth (Quads)
A49: Year | B49: 2014 | C49: 2015 | D49: 2016 | E49: 2017 | F49: 2018 | G49: 2019 | H49: 2020 | I49: 2021 | J49: 2022 | K49: 2023 | L49: 2024 | M49: 2025 | N49: 2026 | O49: 2027 | P49: 2028 | Q49: 2029 | R49: 2030 | S49: 2031 | T49: 2032 | U49: 2033 | V49: 2034 | W49: 2035 | X49: 2036 | Y49: 2037 | Z49: 2038 | AA49: 2039 | AB49: 2040 | AC49: 2041 | AD49: 2042 | AE49: 2043 | AF49: 2044 | AG49: 2045 | AH49: 2046 | AI49: 2047 | AJ49: 2048 | AK49: 2049 | AL49: 2050
...

Sheet Demand by Case
A1: Demand is in Quads | C1: 2010 | D1: 2011 | E1: 2012 | F1: 2013 | G1: 2014 | H1: 2015 | I1: 2016 | J1: 2017 | K1: 2018 | L1: 2019 | M1: 2020 | N1: 2021 | O1: 2022 | P1: 2023 | Q1: 2024 | R1: 2025 | S1: 2026 | T1: 2027 | U1: 2028 | V1: 2029 | W1: 2030 | X1: 2031 | Y1: 2032 | Z1: 2033 | AA1: 2034 | AB1: 2035 | AC1: 2036 | AD1: 2037 | AE1: 2038 | AF1: 2039 | AG1: 2040 | AH1: 2041 | AI1: 2042 | AJ1: 2043 | AK1: 2044 | AL1: 2045 | AM1: 2046 | AN1: 2047 | AO1: 2048 | AP1: 2049 | AQ1: 2050
A2: Reference Case | B2: New England | C2: ='Adding DGPV to Demand'!C32 -> 0.42 | D2: ='Adding DGPV to Demand'!D32 -> 0.411741 | E2: ='Adding DGPV to Demand'!E32 -> 0.410174 | F2: ='Adding DGPV to Demand'!F32 -> 0.41102067 | G2: ='Adding DGPV to Demand'!G32 -> 0.44005517 | H2: ='Adding DGPV to Demand'!H32 -> 0.41126468 | I2: ='Adding DGPV to Demand'!I32 -> 0.40693479 | J2: ='Adding DGPV to Demand'!J32 -> 0.43105186 | ... AQ2: ='Adding DGPV to Demand'!AQ32 -> 0.63884775
A3: Reference Case | B3: Middle Atlantic | C3: ='Adding DGPV to Demand'!C33 -> 1.27 | D3: ='Adding DGPV to Demand'!D33 -> 1.259176 | E3: ='Adding DGPV to Demand'!E33 -> 1.237963 | F3: ='Adding DGPV to Demand'!F33 -> 1.2380461 | G3: ='Adding DGPV to Demand'!G33 -> 1.2675294 | H3: ='Adding DGPV to Demand'!H33 -> 1.2668578 | I3: ='Adding DGPV to Demand'!I33 -> 1.2596388 | J3: ='Adding DGPV to Demand'!J33 -> 1.2369787 | ... AQ3: ='Adding DGPV to Demand'!AQ33 -> 1.9023128
A4: Reference Case | B4: East North Central | C4: ='Adding DGPV to Demand'!C34 -> 1.97 | D4: ='Adding DGPV to Demand'!D34 -> 1.969802 | E4: ='Adding DGPV to Demand'!E34 -> 1.961978 | F4: ='Adding DGPV to Demand'!F34 -> 1.9298374 | G4: ='Adding DGPV to Demand'!G34 -> 1.9455559 | H4: ='Adding DGPV to Demand'!H34 -> 1.9026463 | I4: ='Adding DGPV to Demand'!I34 -> 1.9039976 | J4: ='Adding DGPV to Demand'!J34 -> 1.8747083 | ... AQ4: ='Adding DGPV to Demand'!AQ34 -> 2.749284
A5: Reference Case | B5: West North Central | C5: ='Adding DGPV to Demand'!C35 -> 1.003 | D5: ='Adding DGPV to Demand'!D35 -> 1.004251 | E5: ='Adding DGPV to Demand'!E35 -> 1.002292 | F5: ='Adding DGPV to Demand'!F35 -> 1.0024041 | G5: ='Adding DGPV to Demand'!G35 -> 1.0344766 | H5: ='Adding DGPV to Demand'!H35 -> 1.0144616 | I5: ='Adding DGPV to Demand'!I35 -> 1.0097499 | J5: ='Adding DGPV to Demand'!J35 -> 1.0046327 | ... AQ5: ='Adding DGPV to Demand'!AQ35 -> 1.5969948
A6: Reference Case | B6: South Atlantic | C6: ='Adding DGPV to Demand'!C36 -> 2.815 | D6: ='Adding DGPV to Demand'!D36 -> 2.732388 | E6: ='Adding DGPV to Demand'!E36 -> 2.663072 | F6: ='Adding DGPV to Demand'!F36 -> 2.6758966 | G6: ='Adding DGPV to Demand'!G36 -> 2.7230304 | H6: ='Adding DGPV to Demand'!H36 -> 2.7192014 | I6: ='Adding DGPV to Demand'!I36 -> 2.7304375 | J6: ='Adding DGPV to Demand'!J36 -> 2.6800961 | ... AQ6: ='Adding DGPV to Demand'!AQ36 -> 4.4271166
A7: Reference Case | B7: East South Central | C7: ='Adding DGPV to Demand'!C37 -> 1.152 | D7: ='Adding DGPV to Demand'!D37 -> 1.121258 | E7: ='Adding DGPV to Demand'!E37 -> 1.091933 | F7: ='Adding DGPV to Demand'!F37 -> 1.1197245 | G7: ='Adding DGPV to Demand'!G37 -> 1.0897525 | H7: ='Adding DGPV to Demand'!H37 -> 1.0485683 | I7: ='Adding DGPV to Demand'!I37 -> 1.0376 | J7: ='Adding DGPV to Demand'!J37 -> 1.0056704 | ... AQ7: ='Adding DGPV to Demand'!AQ37 -> 1.4316069
A8: Reference Case | B8: West South Central | C8: ='Adding DGPV to Demand'!C38 -> 1.875 | D8: ='Adding DGPV to Demand'!D38 -> 1.945614 | E8: ='Adding DGPV to Demand'!E38 -> 1.898577 | F8: ='Adding DGPV to Demand'!F38 -> 1.9092153 | G8: ='Adding DGPV to Demand'!G38 -> 2.0292342 | H8: ='Adding DGPV to Demand'!H38 -> 2.0446246 | I8: ='Adding DGPV to Demand'!I38 -> 2.0291272 | J8: ='Adding DGPV to Demand'!J38 -> 2.0232439 | ... AQ8: ='Adding DGPV to Demand'!AQ38 -> 3.5501959
A9: Reference Case | B9: Mountain | C9: ='Adding DGPV to Demand'!C39 -> 0.898 | D9: ='Adding DGPV to Demand'!D39 -> 0.916749 | E9: ='Adding DGPV to Demand'!E39 -> 0.926038 | F9: ='Adding DGPV to Demand'!F39 -> 0.92237836 | G9: ='Adding DGPV to Demand'!G39 -> 0.92273853 | H9: ='Adding DGPV to Demand'!H39 -> 0.93016288 | I9: ='Adding DGPV to Demand'!I39 -> 0.94158965 | J9: ='Adding DGPV to Demand'!J39 -> 0.95548674 | ... AQ9: ='Adding DGPV to Demand'!AQ39 -> 2.0418231
A10: Reference Case | B10: Pacific | C10: ='Adding DGPV to Demand'!C40 -> 1.403 | D10: ='Adding DGPV to Demand'!D40 -> 1.429711 | E10: ='Adding DGPV to Demand'!E40 -> 1.415364 | F10: ='Adding DGPV to Demand'!F40 -> 1.4070579 | G10: ='Adding DGPV to Demand'!G40 -> 1.417766 | H10: ='Adding DGPV to Demand'!H40 -> 1.4341026 | I10: ='Adding DGPV to Demand'!I40 -> 1.430779 | J10: ='Adding DGPV to Demand'!J40 -> 1.4638725 | ... AQ10: ='Adding DGPV to Demand'!AQ40 -> 2.7605744
A11: Reference Case | B11: Total | C11: ='Adding DGPV to Demand'!C41 -> 12.81 | D11: ='Adding DGPV to Demand'!D41 -> 12.79069 | E11: ='Adding DGPV to Demand'!E41 -> 12.607393 | F11: ='Adding DGPV to Demand'!F41 -> 12.615578 | G11: ='Adding DGPV to Demand'!G41 -> 12.87014 | H11: ='Adding DGPV to Demand'!H41 -> 12.771888 | I11: ='Adding DGPV to Demand'!I41 -> 12.749853 | J11: ='Adding DGPV to Demand'!J41 -> 12.675742 | ... AQ11: ='Adding DGPV to Demand'!AQ41 -> 21.098757
A12: High Economic Growth | B12: New England | C12: =C2 -> 0.42 | D12: =D2 -> 0.411741 | E12: =E2 -> 0.410174 | F12: =F2 -> 0.41102067 | G12: =G2 -> 0.44005517 | H12: =H2 -> 0.41126468 | I12: =I2 -> 0.40693479 | J12: =J2 -> 0.43105186 | ... O12: =O2 -> 0.41452341 | P12: ='Adding DGPV to Demand'!K75 -> 0.40785153 | Q12: ='Adding DGPV to Demand'!L75 -> 0.41752414 | R12: ='Adding DGPV to Demand'!M75 -> 0.41878739 | S12: ='Adding DGPV to Demand'!N75 -> 0.423615 | T12: ='Adding DGPV to Demand'!O75 -> 0.43409681 | U12: ='Adding DGPV to Demand'!P75 -> 0.44317519 | V12: ='Adding DGPV to Demand'!Q75 -> 0.45372496 | W12: ='Adding DGPV to Demand'!R75 -> 0.46298284 | ... AQ12: ='Adding DGPV to Demand'!AL75 -> 0.6663686
A13: High Economic Growth | B13: Middle Atlantic | C13: =C3 -> 1.27 | D13: =D3 -> 1.259176 | E13: =E3 -> 1.237963 | F13: =F3 -> 1.2380461 | G13: =G3 -> 1.2675294 | H13: =H3 -> 1.2668578 | I13: =I3 -> 1.2596388 | J13: =J3 -> 1.2369787 | ... O13: =O3 -> 1.2755599 | P13: ='Adding DGPV to Demand'!K76 -> 1.2540192 | Q13: ='Adding DGPV to Demand'!L76 -> 1.2637683 | R13: ='Adding DGPV to Demand'!M76 -> 1.2849116 | S13: ='Adding DGPV to Demand'!N76 -> 1.3019669 | T13: ='Adding DGPV to Demand'!O76 -> 1.3258096 | U13: ='Adding DGPV to Demand'!P76 -> 1.3467811 | V13: ='Adding DGPV to Demand'!Q76 -> 1.373244 | W13: ='Adding DGPV to Demand'!R76 -> 1.3964694 | ... AQ13: ='Adding DGPV to Demand'!AL76 -> 2.0053477
A14: High Economic Growth | B14: East North Central | C14: =C4 -> 1.97 | D14: =D4 -> 1.969802 | E14: =E4 -> 1.961978 | F14: =F4 -> 1.9298374 | G14: =G4 -> 1.9455559 | H14: =H4 -> 1.9026463 | I14: =I4 -> 1.9039976 | J14: =J4 -> 1.8747083 | ... O14: =O4 -> 1.8961219 | P14: ='Adding DGPV to Demand'!K77 -> 1.8825245 | Q14: ='Adding DGPV to Demand'!L77 -> 1.903365 | R14: ='Adding DGPV to Demand'!M77 -> 1.9415255 | S14: ='Adding DGPV to Demand'!N77 -> 1.9704869 | T14: ='Adding DGPV to Demand'!O77 -> 2.0013617 | U14: ='Adding DGPV to Demand'!P77 -> 2.0228089 | V14: ='Adding DGPV to Demand'!Q77 -> 2.0530541 | W14: ='Adding DGPV to Demand'!R77 -> 2.0832415 | ... AQ14: ='Adding DGPV to Demand'!AL77 -> 2.9269711
A15: High Economic Growth | B15: West North Central | C15: =C5 -> 1.003 | D15: =D5 -> 1.004251 | E15: =E5 -> 1.002292 | F15: =F5 -> 1.0024041 | G15: =G5 -> 1.0344766 | H15: =H5 -> 1.0144616 | I15: =I5 -> 1.0097499 | J15: =J5 -> 1.0046327 | ... O15: =O5 -> 1.07271 | P15: ='Adding DGPV to Demand'!K78 -> 1.0616426 | Q15: ='Adding DGPV to Demand'!L78 -> 1.1070117 | R15: ='Adding DGPV to Demand'!M78 -> 1.1249947 | S15: ='Adding DGPV to Demand'!N78 -> 1.1211697 | T15: ='Adding DGPV to Demand'!O78 -> 1.1329834 | U15: ='Adding DGPV to Demand'!P78 -> 1.1408833 | V15: ='Adding DGPV to Demand'!Q78 -> 1.1569959 | W15: ='Adding DGPV to Demand'!R78 -> 1.1747289 | ... AQ15: ='Adding DGPV to Demand'!AL78 -> 1.6919624
A16: High Economic Growth | B16: South Atlantic | C16: =C6 -> 2.815 | D16: =D6 -> 2.732388 | E16: =E6 -> 2.663072 | F16: =F6 -> 2.6758966 | G16: =G6 -> 2.7230304 | H16: =H6 -> 2.7192014 | I16: =I6 -> 2.7304375 | J16: =J6 -> 2.6800961 | ... O16: =O6 -> 2.9142713 | P16: ='Adding DGPV to Demand'!K79 -> 2.9037459 | Q16: ='Adding DGPV to Demand'!L79 -> 2.980832 | R16: ='Adding DGPV to Demand'!M79 -> 3.0147078 | S16: ='Adding DGPV to Demand'!N79 -> 3.0484624 | T16: ='Adding DGPV to Demand'!O79 -> 3.0976611 | U16: ='Adding DGPV to Demand'!P79 -> 3.139148 | V16: ='Adding DGPV to Demand'!Q79 -> 3.1957734 | W16: ='Adding DGPV to Demand'!R79 -> 3.2497801 | ... AQ16: ='Adding DGPV to Demand'!AL79 -> 4.6468284
A17: High Economic Growth | B17: East South Central | C17: =C7 -> 1.152 | D17: =D7 -> 1.121258 | E17: =E7 -> 1.091933 | F17: =F7 -> 1.1197245 | G17: =G7 -> 1.0897525 | H17: =H7 -> 1.0485683 | I17: =I7 -> 1.0376 | J17: =J7 -> 1.0056704 | ... O17: =O7 -> 1.0631943 | P17: ='Adding DGPV to Demand'!K80 -> 1.0575269 | Q17: ='Adding DGPV to Demand'!L80 -> 1.0629012 | R17: ='Adding DGPV to Demand'!M80 -> 1.0624441 | S17: ='Adding DGPV to Demand'!N80 -> 1.0924686 | T17: ='Adding DGPV to Demand'!O80 -> 1.1103418 | U17: ='Adding DGPV to Demand'!P80 -> 1.1229138 | V17: ='Adding DGPV to Demand'!Q80 -> 1.1357179 | W17: ='Adding DGPV to Demand'!R80 -> 1.1491151 | ... AQ17: ='Adding DGPV to Demand'!AL80 -> 1.5368355
A18: High Economic Growth | B18: West South Central | C18: =C8 -> 1.875 | D18: =D8 -> 1.945614 | E18: =E8 -> 1.898577 | F18: =F8 -> 1.9092153 | G18: =G8 -> 2.0292342 | H18: =H8 -> 2.0446246 | I18: =I8 -> 2.0291272 | J18: =J8 -> 2.0232439 | ... O18: =O8 -> 2.3049342 | P18: ='Adding DGPV to Demand'!K81 -> 2.2475091 | Q18: ='Adding DGPV to Demand'!L81 -> 2.3735084 | R18: ='Adding DGPV to Demand'!M81 -> 2.4283258 | S18: ='Adding DGPV to Demand'!N81 -> 2.470332 | T18: ='Adding DGPV to Demand'!O81 -> 2.5115886 | U18: ='Adding DGPV to Demand'!P81 -> 2.5398162 | V18: ='Adding DGPV to Demand'!Q81 -> 2.5805087 | W18: ='Adding DGPV to Demand'!R81 -> 2.6225783 | ... AQ18: ='Adding DGPV to Demand'!AL81 -> 3.8107063
A19: High Economic Growth | B19: Mountain | C19: =C9 -> 0.898 | D19: =D9 -> 0.916749 | E19: =E9 -> 0.926038 | F19: =F9 -> 0.92237836 | G19: =G9 -> 0.92273853 | H19: =H9 -> 0.93016288 | I19: =I9 -> 0.94158965 | J19: =J9 -> 0.95548674 | ... O19: =O9 -> 1.0487647 | P19: ='Adding DGPV to Demand'!K82 -> 1.0385965 | Q19: ='Adding DGPV to Demand'!L82 -> 1.1042444 | R19: ='Adding DGPV to Demand'!M82 -> 1.1127914 | S19: ='Adding DGPV to Demand'!N82 -> 1.1338385 | T19: ='Adding DGPV to Demand'!O82 -> 1.1592617 | U19: ='Adding DGPV to Demand'!P82 -> 1.1816294 | V19: ='Adding DGPV to Demand'!Q82 -> 1.2133538 | W19: ='Adding DGPV to Demand'!R82 -> 1.2479043 | ... AQ19: ='Adding DGPV to Demand'!AL82 -> 2.1776035
A20: High Economic Growth | B20: Pacific | C20: =C10 -> 1.403 | D20: =D10 -> 1.429711 | E20: =E10 -> 1.415364 | F20: =F10 -> 1.4070579 | G20: =G10 -> 1.417766 | H20: =H10 -> 1.4341026 | I20: =I10 -> 1.430779 | J20: =J10 -> 1.4638725 | ... O20: =O10 -> 1.5243844 | P20: ='Adding DGPV to Demand'!K83 -> 1.5142628 | Q20: ='Adding DGPV to Demand'!L83 -> 1.5725669 | R20: ='Adding DGPV to Demand'!M83 -> 1.5720185 | S20: ='Adding DGPV to Demand'!N83 -> 1.6066742 | T20: ='Adding DGPV to Demand'!O83 -> 1.6606211 | U20: ='Adding DGPV to Demand'!P83 -> 1.7048852 | V20: ='Adding DGPV to Demand'!Q83 -> 1.753322 | W20: ='Adding DGPV to Demand'!R83 -> 1.8031427 | ... AQ20: ='Adding DGPV to Demand'!AL83 -> 2.9213171
A21: High Economic Growth | B21: Total | C21: =C11 -> 12.81 | D21: =D11 -> 12.79069 | E21: =E11 -> 12.607393 | F21: =F11 -> 12.615578 | G21: =G11 -> 12.87014 | H21: =H11 -> 12.771888 | I21: =I11 -> 12.749853 | J21: =J11 -> 12.675742 | ... O21: =O11 -> 13.514465 | P21: ='Adding DGPV to Demand'!K84 -> 13.367677 | Q21: ='Adding DGPV to Demand'!L84 -> 13.785723 | R21: ='Adding DGPV to Demand'!M84 -> 13.960506 | S21: ='Adding DGPV to Demand'!N84 -> 14.169014 | T21: ='Adding DGPV to Demand'!O84 -> 14.433726 | U21: ='Adding DGPV to Demand'!P84 -> 14.64204 | V21: ='Adding DGPV to Demand'!Q84 -> 14.915695 | W21: ='Adding DGPV to Demand'!R84 -> 15.189943 | ... AQ21: ='Adding DGPV to Demand'!AL84 -> 22.383939
A22: Low Economic Growth | B22: New England | C22: =C12 -> 0.42 | D22: =D12 -> 0.411741 | E22: =E12 -> 0.410174 | F22: =F12 -> 0.41102067 | G22: =G12 -> 0.44005517 | H22: =H12 -> 0.41126468 | I22: =I12 -> 0.40693479 | J22: =J12 -> 0.43105186 | ... O22: =O12 -> 0.41452341 | P22: ='Adding DGPV to Demand'!K117 -> 0.40633553 | Q22: ='Adding DGPV to Demand'!L117 -> 0.41744131 | R22: ='Adding DGPV to Demand'!M117 -> 0.41585988 | S22: ='Adding DGPV to Demand'!N117 -> 0.41815916 | T22: ='Adding DGPV to Demand'!O117 -> 0.42567005 | U22: ='Adding DGPV to Demand'!P117 -> 0.43251059 | V22: ='Adding DGPV to Demand'!Q117 -> 0.44054354 | W22: ='Adding DGPV to Demand'!R117 -> 0.44783301 | ... AQ22: ='Adding DGPV to Demand'!AL117 -> 0.60754668
A23: Low Economic Growth | B23: Middle Atlantic | C23: =C13 -> 1.27 | D23: =D13 -> 1.259176 | E23: =E13 -> 1.237963 | F23: =F13 -> 1.2380461 | G23: =G13 -> 1.2675294 | H23: =H13 -> 1.2668578 | I23: =I13 -> 1.2596388 | J23: =J13 -> 1.2369787 | ... O23: =O13 -> 1.2755599 | P23: ='Adding DGPV to Demand'!K118 -> 1.2479092 | Q23: ='Adding DGPV to Demand'!L118 -> 1.2635879 | R23: ='Adding DGPV to Demand'!M118 -> 1.2745002 | S23: ='Adding DGPV to Demand'!N118 -> 1.2819883 | T23: ='Adding DGPV to Demand'!O118 -> 1.2961791 | U23: ='Adding DGPV to Demand'!P118 -> 1.3103727 | V23: ='Adding DGPV to Demand'!Q118 -> 1.3287934 | W23: ='Adding DGPV to Demand'!R118 -> 1.3464884 | ... AQ23: ='Adding DGPV to Demand'!AL118 -> 1.8128864
A24: Low Economic Growth | B24: East North Central | C24: =C14 -> 1.97 | D24: =D14 -> 1.969802 | E24: =E14 -> 1.961978 | F24: =F14 -> 1.9298374 | G24: =G14 -> 1.9455559 | H24: =H14 -> 1.9026463 | I24: =I14 -> 1.9039976 | J24: =J14 -> 1.8747083 | ... O24: =O14 -> 1.8961219 | P24: ='Adding DGPV to Demand'!K119 -> 1.8684145 | Q24: ='Adding DGPV to Demand'!L119 -> 1.9032912 | R24: ='Adding DGPV to Demand'!M119 -> 1.9237582 | S24: ='Adding DGPV to Demand'!N119 -> 1.9338405 | T24: ='Adding DGPV to Demand'!O119 -> 1.9483408 | U24: ='Adding DGPV to Demand'!P119 -> 1.9613177 | V24: ='Adding DGPV to Demand'!Q119 -> 1.9795584 | W24: ='Adding DGPV to Demand'!R119 -> 1.9994732 | ... AQ24: ='Adding DGPV to Demand'!AL119 -> 2.6110293
A25: Low Economic Growth | B25: West North Central | C25: =C15 -> 1.003 | D25: =D15 -> 1.004251 | E25: =E15 -> 1.002292 | F25: =F15 -> 1.0024041 | G25: =G15 -> 1.0344766 | H25: =H15 -> 1.0144616 | I25: =I15 -> 1.0097499 | J25: =J15 -> 1.0046327 | ... O25: =O15 -> 1.07271 | P25: ='Adding DGPV to Demand'!K120 -> 1.0542266 | Q25: ='Adding DGPV to Demand'!L120 -> 1.1069823 | R25: ='Adding DGPV to Demand'!M120 -> 1.1152682 | S25: ='Adding DGPV to Demand'!N120 -> 1.1008166 | T25: ='Adding DGPV to Demand'!O120 -> 1.1043046 | U25: ='Adding DGPV to Demand'!P120 -> 1.107963 | V25: ='Adding DGPV to Demand'!Q120 -> 1.1181261 | W25: ='Adding DGPV to Demand'!R120 -> 1.1298235 | ... AQ25: ='Adding DGPV to Demand'!AL120 -> 1.5228546
A26: Low Economic Growth | B26: South Atlantic | C26: =C16 -> 2.815 | D26: =D16 -> 2.732388 | E26: =E16 -> 2.663072 | F26: =F16 -> 2.6758966 | G26: =G16 -> 2.7230304 | H26: =H16 -> 2.7192014 | I26: =I16 -> 2.7304375 | J26: =J16 -> 2.6800961 | ... O26: =O16 -> 2.9142713 | P26: ='Adding DGPV to Demand'!K121 -> 2.8918219 | Q26: ='Adding DGPV to Demand'!L121 -> 2.9805893 | R26: ='Adding DGPV to Demand'!M121 -> 2.9900519 | S26: ='Adding DGPV to Demand'!N121 -> 3.000638 | T26: ='Adding DGPV to Demand'!O121 -> 3.0313283 | U26: ='Adding DGPV to Demand'!P121 -> 3.0604826 | V26: ='Adding DGPV to Demand'!Q121 -> 3.1029264 | W26: ='Adding DGPV to Demand'!R121 -> 3.1399554 | ... AQ26: ='Adding DGPV to Demand'!AL121 -> 4.1922894
A27: Low Economic Growth | B27: East South Central | C27: =C17 -> 1.152 | D27: =D17 -> 1.121258 | E27: =E17 -> 1.091933 | F27: =F17 -> 1.1197245 | G27: =G17 -> 1.0897525 | H27: =H17 -> 1.0485683 | I27: =I17 -> 1.0376 | J27: =J17 -> 1.0056704 | ... O27: =O17 -> 1.0631943 | P27: ='Adding DGPV to Demand'!K122 -> 1.0496959 | Q27: ='Adding DGPV to Demand'!L122 -> 1.062861 | R27: ='Adding DGPV to Demand'!M122 -> 1.0516338 | S27: ='Adding DGPV to Demand'!N122 -> 1.06983 | T27: ='Adding DGPV to Demand'!O122 -> 1.080163 | U27: ='Adding DGPV to Demand'!P122 -> 1.0899173 | V27: ='Adding DGPV to Demand'!Q122 -> 1.0980748 | W27: ='Adding DGPV to Demand'!R122 -> 1.1043211 | ... AQ27: ='Adding DGPV to Demand'!AL122 -> 1.343425
A28: Low Economic Growth | B28: West South Central | C28: =C18 -> 1.875 | D28: =D18 -> 1.945614 | E28: =E18 -> 1.898577 | F28: =F18 -> 1.9092153 | G28: =G18 -> 2.0292342 | H28: =H18 -> 2.0446246 | I28: =I18 -> 2.0291272 | J28: =J18 -> 2.0232439 | ... O28: =O18 -> 2.3049342 | P28: ='Adding DGPV to Demand'!K123 -> 2.2307781 | Q28: ='Adding DGPV to Demand'!L123 -> 2.3733465 | R28: ='Adding DGPV to Demand'!M123 -> 2.4039858 | S28: ='Adding DGPV to Demand'!N123 -> 2.4174522 | T28: ='Adding DGPV to Demand'!O123 -> 2.4362919 | U28: ='Adding DGPV to Demand'!P123 -> 2.4584583 | V28: ='Adding DGPV to Demand'!Q123 -> 2.4861618 | W28: ='Adding DGPV to Demand'!R123 -> 2.5104807 | ... AQ28: ='Adding DGPV to Demand'!AL123 -> 3.3184074
A29: Low Economic Growth | B29: Mountain | C29: =C19 -> 0.898 | D29: =D19 -> 0.916749 | E29: =E19 -> 0.926038 | F29: =F19 -> 0.92237836 | G29: =G19 -> 0.92273853 | H29: =H19 -> 0.93016288 | I29: =I19 -> 0.94158965 | J29: =J19 -> 0.95548674 | ... O29: =O19 -> 1.0487647 | P29: ='Adding DGPV to Demand'!K124 -> 1.0304735 | Q29: ='Adding DGPV to Demand'!L124 -> 1.1041066 | R29: ='Adding DGPV to Demand'!M124 -> 1.1021576 | S29: ='Adding DGPV to Demand'!N124 -> 1.1098994 | T29: ='Adding DGPV to Demand'!O124 -> 1.1258468 | U29: ='Adding DGPV to Demand'!P124 -> 1.1424156 | V29: ='Adding DGPV to Demand'!Q124 -> 1.1665647 | W29: ='Adding DGPV to Demand'!R124 -> 1.1926071 | ... AQ29: ='Adding DGPV to Demand'!AL124 -> 1.9257414
A30: Low Economic Growth | B30: Pacific | C30: =C20 -> 1.403 | D30: =D20 -> 1.429711 | E30: =E20 -> 1.415364 | F30: =F20 -> 1.4070579 | G30: =G20 -> 1.417766 | H30: =H20 -> 1.4341026 | I30: =I20 -> 1.430779 | J30: =J20 -> 1.4638725 | ... O30: =O20 -> 1.5243844 | P30: ='Adding DGPV to Demand'!K125 -> 1.5039898 | Q30: ='Adding DGPV to Demand'!L125 -> 1.5718749 | R30: ='Adding DGPV to Demand'!M125 -> 1.5584598 | S30: ='Adding DGPV to Demand'!N125 -> 1.5780568 | T30: ='Adding DGPV to Demand'!O125 -> 1.6176774 | U30: ='Adding DGPV to Demand'!P125 -> 1.6525747 | V30: ='Adding DGPV to Demand'!Q125 -> 1.6901568 | W30: ='Adding DGPV to Demand'!R125 -> 1.7293004 | ... AQ30: ='Adding DGPV to Demand'!AL125 -> 2.607215
A31: Low Economic Growth | B31: Total | C31: =C21 -> 12.81 | D31: =D21 -> 12.79069 | E31: =E21 -> 12.607393 | F31: =F21 -> 12.615578 | G31: =G21 -> 12.87014 | H31: =H21 -> 12.771888 | I31: =I21 -> 12.749853 | J31: =J21 -> 12.675742 | ... O31: =O21 -> 13.514465 | P31: ='Adding DGPV to Demand'!K126 -> 13.283645 | Q31: ='Adding DGPV to Demand'!L126 -> 13.784082 | R31: ='Adding DGPV to Demand'!M126 -> 13.835674 | S31: ='Adding DGPV to Demand'!N126 -> 13.910682 | T31: ='Adding DGPV to Demand'!O126 -> 14.065802 | U31: ='Adding DGPV to Demand'!P126 -> 14.216014 | V31: ='Adding DGPV to Demand'!Q126 -> 14.410905 | W31: ='Adding DGPV to Demand'!R126 -> 14.600282 | ... AQ31: ='Adding DGPV to Demand'!AL126 -> 19.941396

Sheet Demand Ratios
A1: scenario | B1: cendiv | C1: 2010 | D1: 2011 | E1: 2012 | F1: 2013 | G1: 2014 | H1: 2015 | I1: 2016 | J1: 2017 | K1: 2018 | L1: 2019 | M1: 2020 | N1: 2021 | O1: 2022 | P1: 2023 | Q1: 2024 | R1: 2025 | S1: 2026 | T1: 2027 | U1: 2028 | V1: 2029 | W1: 2030 | X1: 2031 | Y1: 2032 | Z1: 2033 | AA1: 2034 | AB1: 2035 | AC1: 2036 | AD1: 2037 | AE1: 2038 | AF1: 2039 | AG1: 2040 | AH1: 2041 | AI1: 2042 | AJ1: 2043 | AK1: 2044 | AL1: 2045 | AM1: 2046 | AN1: 2047 | AO1: 2048 | AP1: 2049 | AQ1: 2050
A2: Reference Case | B2: NewEngland | C2: ='Demand by Case'!C2/'Demand by Case'!$C2 -> 1 | D2: ='Demand by Case'!D2/'Demand by Case'!$C2 -> 0.98033571 | E2: ='Demand by Case'!E2/'Demand by Case'!$C2 -> 0.97660476 | F2: ='Demand by Case'!F2/'Demand by Case'!$C2 -> 0.97862064 | G2: ='Demand by Case'!G2/'Demand by Case'!$C2 -> 1.0477504 | H2: ='Demand by Case'!H2/'Demand by Case'!$C2 -> 0.97920162 | I2: ='Demand by Case'!I2/'Demand by Case'!$C2 -> 0.96889236 | J2: ='Demand by Case'!J2/'Demand by Case'!$C2 -> 1.026314 | ... AQ2: ='Demand by Case'!AQ2/'Demand by Case'!$C2 -> 1.5210661
A3: Reference Case | B3: MiddleAtlantic | C3: ='Demand by Case'!C3/'Demand by Case'!$C3 -> 1 | D3: ='Demand by Case'!D3/'Demand by Case'!$C3 -> 0.99147717 | E3: ='Demand by Case'!E3/'Demand by Case'!$C3 -> 0.97477402 | F3: ='Demand by Case'!F3/'Demand by Case'!$C3 -> 0.97483945 | G3: ='Demand by Case'!G3/'Demand by Case'!$C3 -> 0.99805462 | H3: ='Demand by Case'!H3/'Demand by Case'!$C3 -> 0.99752583 | I3: ='Demand by Case'!I3/'Demand by Case'!$C3 -> 0.99184159 | J3: ='Demand by Case'!J3/'Demand by Case'!$C3 -> 0.97399899 | ... AQ3: ='Demand by Case'!AQ3/'Demand by Case'!$C3 -> 1.4978841
A4: Reference Case | B4: EastNorthCentral | C4: ='Demand by Case'!C4/'Demand by Case'!$C4 -> 1 | D4: ='Demand by Case'!D4/'Demand by Case'!$C4 -> 0.99989949 | E4: ='Demand by Case'!E4/'Demand by Case'!$C4 -> 0.99592792 | F4: ='Demand by Case'!F4/'Demand by Case'!$C4 -> 0.97961287 | G4: ='Demand by Case'!G4/'Demand by Case'!$C4 -> 0.98759181 | H4: ='Demand by Case'!H4/'Demand by Case'!$C4 -> 0.96581029 | I4: ='Demand by Case'!I4/'Demand by Case'!$C4 -> 0.96649624 | J4: ='Demand by Case'!J4/'Demand by Case'!$C4 -> 0.95162859 | ... AQ4: ='Demand by Case'!AQ4/'Demand by Case'!$C4 -> 1.3955757
A5: Reference Case | B5: WestNorthCentral | C5: ='Demand by Case'!C5/'Demand by Case'!$C5 -> 1 | D5: ='Demand by Case'!D5/'Demand by Case'!$C5 -> 1.0012473 | E5: ='Demand by Case'!E5/'Demand by Case'!$C5 -> 0.99929412 | F5: ='Demand by Case'!F5/'Demand by Case'!$C5 -> 0.99940586 | G5: ='Demand by Case'!G5/'Demand by Case'!$C5 -> 1.0313825 | H5: ='Demand by Case'!H5/'Demand by Case'!$C5 -> 1.0114273 | I5: ='Demand by Case'!I5/'Demand by Case'!$C5 -> 1.0067297 | J5: ='Demand by Case'!J5/'Demand by Case'!$C5 -> 1.0016278 | ... AQ5: ='Demand by Case'!AQ5/'Demand by Case'!$C5 -> 1.5922182
A6: Reference Case | B6: SouthAtlantic | C6: ='Demand by Case'!C6/'Demand by Case'!$C6 -> 1 | D6: ='Demand by Case'!D6/'Demand by Case'!$C6 -> 0.97065293 | E6: ='Demand by Case'!E6/'Demand by Case'!$C6 -> 0.94602913 | F6: ='Demand by Case'!F6/'Demand by Case'!$C6 -> 0.95058492 | G6: ='Demand by Case'!G6/'Demand by Case'!$C6 -> 0.96732874 | H6: ='Demand by Case'!H6/'Demand by Case'!$C6 -> 0.96596853 | I6: ='Demand by Case'!I6/'Demand by Case'!$C6 -> 0.96996002 | J6: ='Demand by Case'!J6/'Demand by Case'!$C6 -> 0.95207676 | ... AQ6: ='Demand by Case'!AQ6/'Demand by Case'!$C6 -> 1.572688
A7: Reference Case | B7: EastSouthCentral | C7: ='Demand by Case'!C7/'Demand by Case'!$C7 -> 1 | D7: ='Demand by Case'!D7/'Demand by Case'!$C7 -> 0.97331424 | E7: ='Demand by Case'!E7/'Demand by Case'!$C7 -> 0.94785851 | F7: ='Demand by Case'!F7/'Demand by Case'!$C7 -> 0.97198306 | G7: ='Demand by Case'!G7/'Demand by Case'!$C7 -> 0.94596575 | H7: ='Demand by Case'!H7/'Demand by Case'!$C7 -> 0.91021556 | I7: ='Demand by Case'!I7/'Demand by Case'!$C7 -> 0.90069445 | J7: ='Demand by Case'!J7/'Demand by Case'!$C7 -> 0.87297773 | ... AQ7: ='Demand by Case'!AQ7/'Demand by Case'!$C7 -> 1.2427143
A8: Reference Case | B8: WestSouthCentral | C8: ='Demand by Case'!C8/'Demand by Case'!$C8 -> 1 | D8: ='Demand by Case'!D8/'Demand by Case'!$C8 -> 1.0376608 | E8: ='Demand by Case'!E8/'Demand by Case'!$C8 -> 1.0125744 | F8: ='Demand by Case'!F8/'Demand by Case'!$C8 -> 1.0182482 | G8: ='Demand by Case'!G8/'Demand by Case'!$C8 -> 1.0822582 | H8: ='Demand by Case'!H8/'Demand by Case'!$C8 -> 1.0904665 | I8: ='Demand by Case'!I8/'Demand by Case'!$C8 -> 1.0822012 | J8: ='Demand by Case'!J8/'Demand by Case'!$C8 -> 1.0790634 | ... AQ8: ='Demand by Case'!AQ8/'Demand by Case'!$C8 -> 1.8934378
A9: Reference Case | B9: Mountain | C9: ='Demand by Case'!C9/'Demand by Case'!$C9 -> 1 | D9: ='Demand by Case'!D9/'Demand by Case'!$C9 -> 1.0208786 | E9: ='Demand by Case'!E9/'Demand by Case'!$C9 -> 1.0312227 | F9: ='Demand by Case'!F9/'Demand by Case'!$C9 -> 1.0271474 | G9: ='Demand by Case'!G9/'Demand by Case'!$C9 -> 1.0275485 | H9: ='Demand by Case'!H9/'Demand by Case'!$C9 -> 1.0358161 | I9: ='Demand by Case'!I9/'Demand by Case'!$C9 -> 1.0485408 | J9: ='Demand by Case'!J9/'Demand by Case'!$C9 -> 1.0640164 | ... AQ9: ='Demand by Case'!AQ9/'Demand by Case'!$C9 -> 2.2737451
A10: Reference Case | B10: Pacific | C10: ='Demand by Case'!C10/'Demand by Case'!$C10 -> 1 | D10: ='Demand by Case'!D10/'Demand by Case'!$C10 -> 1.0190385 | E10: ='Demand by Case'!E10/'Demand by Case'!$C10 -> 1.0088125 | F10: ='Demand by Case'!F10/'Demand by Case'!$C10 -> 1.0028923 | G10: ='Demand by Case'!G10/'Demand by Case'!$C10 -> 1.0105246 | H10: ='Demand by Case'!H10/'Demand by Case'!$C10 -> 1.0221687 | I10: ='Demand by Case'!I10/'Demand by Case'!$C10 -> 1.0197997 | J10: ='Demand by Case'!J10/'Demand by Case'!$C10 -> 1.0433874 | ... AQ10: ='Demand by Case'!AQ10/'Demand by Case'!$C10 -> 1.9676225
A11: Reference Case | B11: Total | C11: ='Demand by Case'!C11/'Demand by Case'!$C11 -> 1 | D11: ='Demand by Case'!D11/'Demand by Case'!$C11 -> 0.99849258 | E11: ='Demand by Case'!E11/'Demand by Case'!$C11 -> 0.98418368 | F11: ='Demand by Case'!F11/'Demand by Case'!$C11 -> 0.98482263 | G11: ='Demand by Case'!G11/'Demand by Case'!$C11 -> 1.0046947 | H11: ='Demand by Case'!H11/'Demand by Case'!$C11 -> 0.99702484 | I11: ='Demand by Case'!I11/'Demand by Case'!$C11 -> 0.99530472 | J11: ='Demand by Case'!J11/'Demand by Case'!$C11 -> 0.9895193 | ... AQ11: ='Demand by Case'!AQ11/'Demand by Case'!$C11 -> 1.6470537
A12: High Economic Growth | B12: NewEngland | C12: ='Demand by Case'!C12/'Demand by Case'!$C12 -> 1 | D12: ='Demand by Case'!D12/'Demand by Case'!$C12 -> 0.98033571 | E12: ='Demand by Case'!E12/'Demand by Case'!$C12 -> 0.97660476 | F12: ='Demand by Case'!F12/'Demand by Case'!$C12 -> 0.97862064 | G12: ='Demand by Case'!G12/'Demand by Case'!$C12 -> 1.0477504 | H12: ='Demand by Case'!H12/'Demand by Case'!$C12 -> 0.97920162 | I12: ='Demand by Case'!I12/'Demand by Case'!$C12 -> 0.96889236 | J12: ='Demand by Case'!J12/'Demand by Case'!$C12 -> 1.026314 | ... AQ12: ='Demand by Case'!AQ12/'Demand by Case'!$C12 -> 1.5865919
A13: High Economic Growth | B13: MiddleAtlantic | C13: ='Demand by Case'!C13/'Demand by Case'!$C13 -> 1 | D13: ='Demand by Case'!D13/'Demand by Case'!$C13 -> 0.99147717 | E13: ='Demand by Case'!E13/'Demand by Case'!$C13 -> 0.97477402 | F13: ='Demand by Case'!F13/'Demand by Case'!$C13 -> 0.97483945 | G13: ='Demand by Case'!G13/'Demand by Case'!$C13 -> 0.99805462 | H13: ='Demand by Case'!H13/'Demand by Case'!$C13 -> 0.99752583 | I13: ='Demand by Case'!I13/'Demand by Case'!$C13 -> 0.99184159 | J13: ='Demand by Case'!J13/'Demand by Case'!$C13 -> 0.97399899 | ... AQ13: ='Demand by Case'!AQ13/'Demand by Case'!$C13 -> 1.5790139
... A31: Low Economic Growth | B31: Total | C31: ='Demand by Case'!C31/'Demand by Case'!$C31 -> 1 | D31: ='Demand by Case'!D31/'Demand by Case'!$C31 -> 0.99849258 | E31: ='Demand by Case'!E31/'Demand by Case'!$C31 -> 0.98418368 | F31: ='Demand by Case'!F31/'Demand by Case'!$C31 -> 0.98482263 | G31: ='Demand by Case'!G31/'Demand by Case'!$C31 -> 1.0046947 | H31: ='Demand by Case'!H31/'Demand by Case'!$C31 -> 0.99702484 | I31: ='Demand by Case'!I31/'Demand by Case'!$C31 -> 0.99530472 | J31: ='Demand by Case'!J31/'Demand by Case'!$C31 -> 0.9895193 | ... AQ31: ='Demand by Case'!AQ31/'Demand by Case'!$C31 -> 1.5567054
