Workbook
Name IQ_CH: 110000
Name IQ_CQ: 5000
Name IQ_CY: 10000
Name IQ_DAILY: 500000
Name IQ_FH: 100000
Name IQ_FQ: 500
Name IQ_FY: 1000
Name IQ_LTM: 2000
Name IQ_MONTH: 15000
Name IQ_NTM: 6000
Name IQ_WEEK: 50000
Name IQ_YTD: 3000

Sheet Prices by Case
A1: Prices are 2024$/MMBTU | C1: 2010 | D1: 2011 | E1: 2012 | F1: 2013 | G1: 2014 | H1: 2015 | I1: 2016 | J1: 2017 | K1: 2018 | L1: 2019 | M1: 2020 | N1: 2021 | O1: 2022 | P1: 2023 | Q1: 2024 | R1: 2025 | S1: 2026 | T1: 2027 | U1: 2028 | V1: 2029 | W1: 2030 | X1: 2031 | Y1: 2032 | Z1: 2033 | AA1: 2034 | AB1: 2035 | AC1: 2036 | AD1: 2037 | AE1: 2038 | AF1: 2039 | AG1: 2040 | AH1: 2041 | AI1: 2042 | AJ1: 2043 | AK1: 2044 | AL1: 2045 | AM1: 2046 | AN1: 2047 | AO1: 2048 | AP1: 2049 | AQ1: 2050
A2: Reference Case | B2: East North Central | C2: 7.0909945 | D2: 6.4152443 | E2: 4.3183963 | F2: 5.6445716 | G2: 6.9015738 | H2: 3.7284693 | I2: 3.6043293 | J2: 4.2513316 | K2: 4.0830606 | L2: 3.0741546 | M2: 2.4336008 | N2: 5.2120499 | O2: 6.7368105 | P2: 2.5766965 | Q2: 2.28508 | R2: 2.837277 | S2: 2.763278 | T2: 2.703812 | U2: 2.762565 | V2: 2.91825 | W2: 3.049576 | X2: 3.170081 | Y2: 3.635774 | Z2: 3.881344 | AA2: 3.987692 | AB2: 4.04547 | AC2: 4.036805 | AD2: 3.899876 | AE2: 3.733063 | AF2: 3.681409 | AG2: 3.662889 | AH2: 3.723782 | AI2: 3.77397 | AJ2: 3.805754 | AK2: 3.800041 | AL2: 3.79805 | AM2: 3.810532 | AN2: 3.770669 | AO2: 3.740844 | AP2: 3.685088 | AQ2: 3.642668
A3: Reference Case | B3: East South Central | C3: 6.864627 | D3: 6.035803 | E3: 4.1713368 | F3: 5.4256613 | G3: 6.1961337 | H3: 3.831858 | I3: 3.3489419 | J3: 4.060241 | K3: 4.0259849 | L3: 3.2921435 | M3: 2.7713176 | N3: 5.9408672 | O3: 7.9109311 | P3: 2.9342711 | Q3: 2.645327 | R3: 3.142428 | S3: 3.055122 | T3: 2.988694 | U3: 3.127218 | V3: 3.306478 | W3: 3.512392 | X3: 3.613755 | Y3: 4.085257 | Z3: 4.388517 | AA3: 4.544195 | AB3: 4.609845 | AC3: 4.556694 | AD3: 4.464017 | AE3: 4.376263 | AF3: 4.286094 | AG3: 4.299133 | AH3: 4.361627 | AI3: 4.390012 | AJ3: 4.522407 | AK3: 4.578125 | AL3: 4.596054 | AM3: 4.665256 | AN3: 4.652761 | AO3: 4.571362 | AP3: 4.388964 | AQ3: 4.235358
A4: Reference Case | B4: Middle Atlantic | C4: 7.8163645 | D4: 7.1816099 | E4: 4.9209548 | F4: 6.2217721 | G4: 6.7497856 | H4: 3.85032 | I4: 3.6610677 | J4: 4.1596902 | K4: 4.2283623 | L4: 3.5693198 | M4: 2.9222609 | N4: 5.3239298 | O4: 6.1751711 | P4: 3.0940898 | Q4: 2.26953 | R4: 2.724665 | S4: 2.780215 | T4: 2.636923 | U4: 2.576812 | V4: 2.643674 | W4: 2.773706 | X4: 2.866469 | Y4: 3.222987 | Z4: 3.483385 | AA4: 3.598001 | AB4: 3.631619 | AC4: 3.610814 | AD4: 3.518157 | AE4: 3.376865 | AF4: 3.256926 | AG4: 3.215503 | AH4: 3.252421 | AI4: 3.298153 | AJ4: 3.344024 | AK4: 3.347215 | AL4: 3.329523 | AM4: 3.393556 | AN4: 3.383668 | AO4: 3.349662 | AP4: 3.274235 | AQ4: 3.161351
A5: Reference Case | B5: Mountain | C5: 7.2146331 | D5: 6.7590397 | E5: 4.8126922 | F5: 6.026714 | G5: 6.5332483 | H5: 4.2834864 | I5: 3.5443836 | J5: 4.1952504 | K5: 4.3117017 | L5: 3.5556914 | M5: 3.1170105 | N5: 6.2959381 | O5: 7.8164372 | P5: 3.3002907 | Q5: 2.841191 | R5: 3.296411 | S5: 3.156343 | T5: 3.122164 | U5: 3.269873 | V5: 3.513918 | W5: 3.861304 | X5: 4.079747 | Y5: 4.733683 | Z5: 5.040173 | AA5: 5.230925 | AB5: 5.303466 | AC5: 5.251937 | AD5: 5.176685 | AE5: 5.154803 | AF5: 5.160571 | AG5: 5.306404 | AH5: 5.505489 | AI5: 5.683669 | AJ5: 5.836872 | AK5: 5.905303 | AL5: 5.9452 | AM5: 6.013248 | AN5: 6.069484 | AO5: 6.010077 | AP5: 5.912456 | AQ5: 5.97212
A6: Reference Case | B6: New England | C6: 7.7704295 | D6: 6.9766058 | E6: 5.1256877 | F6: 8.0681247 | G6: 8.7692015 | H6: 5.6641395 | I6: 5.1482992 | J6: 5.3552845 | K6: 5.8812538 | L6: 5.4764621 | M6: 4.8945566 | N6: 7.9478483 | O6: 8.9289088 | P6: 5.1823565 | Q6: 3.914745 | R6: 3.945919 | S6: 3.819109 | T6: 3.43536 | U6: 3.240752 | V6: 3.229812 | W6: 3.129285 | X6: 3.326129 | Y6: 3.779099 | Z6: 4.071227 | AA6: 4.168971 | AB6: 4.199443 | AC6: 4.265835 | AD6: 4.120316 | AE6: 3.99361 | AF6: 3.816716 | AG6: 3.872509 | AH6: 3.966687 | AI6: 4.091134 | AJ6: 4.169929 | AK6: 4.087124 | AL6: 3.891919 | AM6: 3.902629 | AN6: 3.945969 | AO6: 3.787596 | AP6: 3.870886 | AQ6: 3.788044
A7: Reference Case | B7: Pacific | C7: 6.922075 | D7: 6.523092 | E7: 4.981963 | F7: 5.9665944 | G7: 6.6528652 | H7: 4.3182277 | I7: 3.6670861 | J7: 4.1891584 | K7: 4.317322 | L7: 3.7488371 | M7: 3.305045 | N7: 6.7127102 | O7: 8.0403982 | P7: 3.4993816 | Q7: 3.178771 | R7: 3.449765 | S7: 3.232441 | T7: 3.154894 | U7: 3.344125 | V7: 3.63497 | W7: 4.01986 | X7: 4.274564 | Y7: 4.89114 | Z7: 5.191451 | AA7: 5.384827 | AB7: 5.41206 | AC7: 5.28292 | AD7: 5.104523 | AE7: 5.010477 | AF7: 4.923649 | AG7: 5.055543 | AH7: 5.287903 | AI7: 5.408764 | AJ7: 5.563621 | AK7: 5.645613 | AL7: 5.636967 | AM7: 5.758965 | AN7: 5.808951 | AO7: 5.813332 | AP7: 5.796697 | AQ7: 5.74582
A8: Reference Case | B8: South Atlantic | C8: 8.6455875 | D8: 7.6126831 | E8: 5.7441422 | F8: 6.4880623 | G8: 7.2176795 | H8: 5.2096383 | I8: 4.5142802 | J8: 4.872571 | K8: 4.6931878 | L8: 4.0989787 | M8: 3.5356091 | N8: 6.6328158 | O8: 8.5436921 | P8: 3.7435029 | Q8: 3.581676 | R8: 3.846201 | S8: 3.765639 | T8: 3.837702 | U8: 3.78544 | V8: 4.085795 | W8: 4.087484 | X8: 4.101537 | Y8: 4.559186 | Z8: 4.842482 | AA8: 4.962396 | AB8: 5.016607 | AC8: 5.044314 | AD8: 4.979167 | AE8: 4.909653 | AF8: 4.850672 | AG8: 4.854046 | AH8: 4.880734 | AI8: 4.925858 | AJ8: 5.008918 | AK8: 5.012309 | AL8: 4.970164 | AM8: 4.994895 | AN8: 4.917217 | AO8: 4.80245 | AP8: 4.690213 | AQ8: 4.578797
A9: Reference Case | B9: West North Central | C9: 7.7342883 | D9: 7.1878304 | E9: 4.8369682 | F9: 6.2173975 | G9: 7.3986154 | H9: 4.4282166 | I9: 3.5004066 | J9: 4.469497 | K9: 4.3344102 | L9: 3.3526082 | M9: 2.854164 | N9: 5.658208 | O9: 7.6279947 | P9: 3.0219888 | Q9: 2.605072 | R9: 3.162053 | S9: 3.076137 | T9: 3.054238 | U9: 3.195382 | V9: 3.398271 | W9: 3.646155 | X9: 3.762861 | Y9: 4.423059 | Z9: 4.704285 | AA9: 4.772688 | AB9: 4.784186 | AC9: 4.780307 | AD9: 4.672058 | AE9: 4.56643 | AF9: 4.408439 | AG9: 4.491251 | AH9: 4.649086 | AI9: 4.751801 | AJ9: 4.807343 | AK9: 4.817755 | AL9: 4.839172 | AM9: 4.945189 | AN9: 4.90954 | AO9: 4.859097 | AP9: 4.774216 | AQ9: 4.791852
A10: Reference Case | B10: West South Central | C10: 6.6138471 | D10: 6.0219341 | E10: 4.0862421 | F10: 5.3117253 | G10: 6.1419078 | H10: 3.7096081 | I10: 3.0974698 | J10: 3.8143408 | K10: 3.7845595 | L10: 2.8508973 | M10: 2.3729458 | N10: 5.4412251 | O10: 7.3605167 | P10: 2.5124751 | Q10: 2.19948 | R10: 2.702884 | S10: 2.602545 | T10: 2.549224 | U10: 2.701754 | V10: 2.910596 | W10: 3.163967 | X10: 3.303848 | Y10: 3.843493 | Z10: 4.214373 | AA10: 4.409548 | AB10: 4.425838 | AC10: 4.374448 | AD10: 4.317363 | AE10: 4.273121 | AF10: 4.233821 | AG10: 4.305593 | AH10: 4.432408 | AI10: 4.548378 | AJ10: 4.704851 | AK10: 4.813431 | AL10: 4.858135 | AM10: 4.923351 | AN10: 5.001916 | AO10: 5.000763 | AP10: 4.946911 | AQ10: 4.904408
A11: Reference Case | B11: Total | C11: 7.4287481 | D11: 6.7037263 | E11: 4.7928849 | F11: 5.9972716 | G11: 6.7346123 | H11: 4.2877226 | I11: 3.748361 | J11: 4.325765 | K11: 4.2709841 | L11: 3.5042841 | M11: 2.9645883 | N11: 5.9572672 | O11: 7.5198121 | P11: 3.1389061 | Q11: 2.723915 | R11: 3.156929 | S11: 3.07397 | T11: 3.015308 | U11: 3.070505 | V11: 3.264617 | W11: 3.431582 | X11: 3.550639 | Y11: 4.043609 | Z11: 4.324777 | AA11: 4.470538 | AB11: 4.519019 | AC11: 4.501416 | AD11: 4.410881 | AE11: 4.34083 | AF11: 4.281797 | AG11: 4.309677 | AH11: 4.398407 | AI11: 4.485073 | AJ11: 4.569963 | AK11: 4.592783 | AL11: 4.585633 | AM11: 4.621171 | AN11: 4.628467 | AO11: 4.585876 | AP11: 4.521132 | AQ11: 4.459167
A12: High O&G Resource | B12: East North Central | C12: 7.0909945 | D12: 6.4152443 | E12: 4.3183963 | F12: 5.6445716 | G12: 6.9015738 | H12: 3.7284693 | I12: 3.6043293 | J12: 4.2513316 | K12: 4.0830606 | L12: 3.0741546 | M12: 2.4336008 | N12: 5.2120499 | O12: 6.7368105 | P12: 2.5766965 | Q12: 2.298708 | R12: 2.394202 | S12: 2.279395 | T12: 2.267412 | U12: 2.342423 | V12: 2.422638 | W12: 2.509715 | X12: 2.525936 | Y12: 2.816504 | Z12: 2.860132 | AA12: 2.896689 | AB12: 2.911631 | AC12: 2.902459 | AD12: 2.849265 | AE12: 2.787631 | AF12: 2.754783 | AG12: 2.765788 | AH12: 2.809392 | AI12: 2.803964 | AJ12: 2.752379 | AK12: 2.68326 | AL12: 2.62781 | AM12: 2.628173 | AN12: 2.562113 | AO12: 2.51238 | AP12: 2.461685 | AQ12: 2.421813
A13: High O&G Resource | B13: East South Central | C13: 6.864627 | D13: 6.035803 | E13: 4.1713368 | F13: 5.4256613 | G13: 6.1961337 | H13: 3.831858 | I13: 3.3489419 | J13: 4.060241 | K13: 4.0259849 | L13: 3.2921435 | M13: 2.7713176 | N13: 5.9408672 | O13: 7.9109311 | P13: 2.9342711 | Q13: 2.680677 | R13: 2.663157 | S13: 2.498695 | T13: 2.484879 | U13: 2.607332 | V13: 2.709477 | W13: 2.835151 | X13: 2.905147 | Y13: 3.177044 | Z13: 3.242102 | AA13: 3.271004 | AB13: 3.285653 | AC13: 3.277782 | AD13: 3.248419 | AE13: 3.233404 | AF13: 3.219203 | AG13: 3.249156 | AH13: 3.310269 | AI13: 3.32616 | AJ13: 3.289931 | AK13: 3.263479 | AL13: 3.24825 | AM13: 3.277446 | AN13: 3.260696 | AO13: 3.256391 | AP13: 3.213834 | AQ13: 3.162359
... A31: Low O&G Resource | B31: Total | C31: 7.4287481 | D31: 6.7037263 | E31: 4.7928849 | F31: 5.9972716 | G31: 6.7346123 | H31: 4.2877226 | I31: 3.748361 | J31: 4.325765 | K31: 4.2709841 | L31: 3.5042841 | M31: 2.9645883 | N31: 5.9572672 | O31: 7.5198121 | P31: 3.1389061 | Q31: 2.719761 | R31: 4.077515 | S31: 4.10874 | T31: 4.2087 | U31: 4.498169 | V31: 4.95927 | W31: 5.868904 | X31: 6.432722 | Y31: 7.285527 | Z31: 7.591053 | AA31: 7.793079 | AB31: 7.919057 | AC31: 8.122101 | AD31: 8.129334 | AE31: 7.99989 | AF31: 8.112631 | AG31: 8.127403 | AH31: 8.08535 | AI31: 7.947904 | AJ31: 7.796221 | AK31: 7.89953 | AL31: 7.902833 | AM31: 7.967216 | AN31: 8.250522 | AO31: 8.585338 | AP31: 8.887414 | AQ31: 9.218601
P32: Note: 2023 year in the 2025 projected was adjusted based on the ratio between 2020 NG Henry Hub prices and the 2023 NG Henry Hub prices
C33: 1.071189 | D33: Inflation

Sheet Demand by Case
A1: Demand in Quads | C1: 2010 | D1: 2011 | E1: 2012 | F1: 2013 | G1: 2014 | H1: 2015 | I1: 2016 | J1: 2017 | K1: 2018 | L1: 2019 | M1: 2020 | N1: 2021 | O1: 2022 | P1: 2023 | Q1: 2024 | R1: 2025 | S1: 2026 | T1: 2027 | U1: 2028 | V1: 2029 | W1: 2030 | X1: 2031 | Y1: 2032 | Z1: 2033 | AA1: 2034 | AB1: 2035 | AC1: 2036 | AD1: 2037 | AE1: 2038 | AF1: 2039 | AG1: 2040 | AH1: 2041 | AI1: 2042 | AJ1: 2043 | AK1: 2044 | AL1: 2045 | AM1: 2046 | AN1: 2047 | AO1: 2048 | AP1: 2049 | AQ1: 2050
A2: Reference Case | B2: East North Central | C2: 0.326 | D2: 0.395 | E2: 0.6556 | F2: 0.4753 | G2: 0.48286 | H2: 0.71331 | I2: 0.91214 | J2: 0.81026 | K2: 1.00257 | L2: 1.185716 | M2: 1.262778 | N2: 1.082247 | O2: 1.477695 | P2: =1.0588*M2 -> 1.3370293 | Q2: 1.803768 | R2: 1.77915 | S2: 1.709301 | T2: 1.930932 | U2: 2.042475 | V2: 2.250298 | W2: 2.271644 | X2: 2.249849 | Y2: 2.753094 | Z2: 2.61021 | AA2: 2.315766 | AB2: 2.12818 | AC2: 1.923508 | AD2: 1.718799 | AE2: 1.530699 | AF2: 1.492246 | AG2: 1.538328 | AH2: 1.606427 | AI2: 1.636847 | AJ2: 1.703603 | AK2: 1.783943 | AL2: 1.743539 | AM2: 1.815236 | AN2: 1.637457 | AO2: 1.609448 | AP2: 1.616478 | AQ2: 1.626209
A3: Reference Case | B3: East South Central | C3: 0.567 | D3: 0.639 | E3: 0.7973 | F3: 0.62896 | G3: 0.67191 | H3: 0.87542 | I3: 0.9619 | J3: 0.9109 | K3: 0.994602 | L3: 1.029824 | M3: 1.047204 | N3: 0.913914 | O3: 0.90048 | P3: =1.0588*M3 -> 1.1087796 | Q3: 1.120752 | R3: 1.098819 | S3: 1.090066 | T3: 1.157464 | U3: 1.160019 | V3: 1.124709 | W3: 1.037678 | X3: 0.989105 | Y3: 1.045986 | Z3: 0.955824 | AA3: 0.866626 | AB3: 0.824893 | AC3: 0.771852 | AD3: 0.714015 | AE3: 0.654886 | AF3: 0.603034 | AG3: 0.603428 | AH3: 0.615171 | AI3: 0.61597 | AJ3: 0.590668 | AK3: 0.604031 | AL3: 0.610125 | AM3: 0.608258 | AN3: 0.593526 | AO3: 0.605255 | AP3: 0.636592 | AQ3: 0.643452
A4: Reference Case | B4: Middle Atlantic | C4: 0.89 | D4: 0.965 | E4: 1.15412 | F4: 1.06634 | G4: 1.13148 | H4: 1.23645 | I4: 1.3445 | J4: 1.19616 | K4: 1.300064 | L4: 1.451554 | M4: 1.684218 | N4: 1.654776 | O4: 1.998293 | P4: =1.0588*M4 -> 1.78325 | Q4: 1.947869 | R4: 1.629397 | S4: 1.645651 | T4: 1.664455 | U4: 1.601191 | V4: 1.567711 | W4: 1.638802 | X4: 1.537363 | Y4: 1.631743 | Z4: 1.585095 | AA4: 1.527352 | AB4: 1.546738 | AC4: 1.530112 | AD4: 1.373293 | AE4: 1.208284 | AF4: 1.129269 | AG4: 1.131776 | AH4: 1.15756 | AI4: 1.098378 | AJ4: 1.162631 | AK4: 1.205421 | AL4: 1.299167 | AM4: 1.281461 | AN4: 1.37779 | AO4: 1.420297 | AP4: 1.3456 | AQ4: 1.342685
A5: Reference Case | B5: Mountain | C5: 0.641 | D5: 0.567 | E5: 0.66283 | F5: 0.65072 | G5: 0.64891 | H5: 0.75092 | I5: 0.76576 | J5: 0.69033 | K5: 0.760259 | L5: 0.988215 | M5: 0.954761 | N5: 0.947247 | O5: 0.947744 | P5: =1.0588*M5 -> 1.0109009 | Q5: 1.202134 | R5: 1.095031 | S5: 1.009045 | T5: 1.0129 | U5: 0.970603 | V5: 0.961866 | W5: 1.036249 | X5: 1.062644 | Y5: 1.131738 | Z5: 0.945356 | AA5: 0.872272 | AB5: 0.893621 | AC5: 0.882123 | AD5: 0.846004 | AE5: 0.834513 | AF5: 0.853311 | AG5: 0.86345 | AH5: 0.862811 | AI5: 0.91582 | AJ5: 0.912592 | AK5: 0.939069 | AL5: 0.952057 | AM5: 0.916862 | AN5: 0.906929 | AO5: 0.957831 | AP5: 0.998673 | AQ5: 1.03689
A6: Reference Case | B6: New England | C6: 0.42 | D6: 0.456 | E6: 0.44768 | F6: 0.37155 | G6: 0.34175 | H6: 0.39761 | I6: 0.39318 | J6: 0.37141 | K6: 0.400407 | L6: 0.338651 | M6: 0.360853 | N6: 0.344592 | O6: 0.366773 | P6: 0.38207116 | Q6: 0.451624 | R6: 0.402601 | S6: 0.307184 | T6: 0.263452 | U6: 0.243434 | V6: 0.223449 | W6: 0.172437 | X6: 0.193628 | Y6: 0.210223 | Z6: 0.20238 | AA6: 0.189251 | AB6: 0.192515 | AC6: 0.197367 | AD6: 0.189569 | AE6: 0.194608 | AF6: 0.18355 | AG6: 0.191371 | AH6: 0.192375 | AI6: 0.203848 | AJ6: 0.207948 | AK6: 0.183532 | AL6: 0.141631 | AM6: 0.157335 | AN6: 0.158988 | AO6: 0.162292 | AP6: 0.174212 | AQ6: 0.165085
A7: Reference Case | B7: Pacific | C7: 0.989 | D7: 0.766 | E7: 1.04455 | F7: 1.06898 | G7: 1.07373 | H7: 1.08443 | I7: 0.91791 | J7: 0.8409 | K7: 0.871735 | L7: 0.834003 | M7: 0.847681 | N7: 0.887034 | O7: 0.850175 | P7: =1.0588*M7 -> 0.89752464 | Q7: 1.026979 | R7: 0.855043 | S7: 0.751345 | T7: 0.718387 | U7: 0.776476 | V7: 0.824927 | W7: 0.894584 | X7: 0.947843 | Y7: 1.00009 | Z7: 0.930929 | AA7: 0.947975 | AB7: 0.933309 | AC7: 0.888036 | AD7: 0.825748 | AE7: 0.78475 | AF7: 0.737564 | AG7: 0.723354 | AH7: 0.729275 | AI7: 0.673652 | AJ7: 0.706872 | AK7: 0.684177 | AL7: 0.662889 | AM7: 0.618836 | AN7: 0.640318 | AO7: 0.637655 | AP7: 0.629154 | AQ7: 0.621188
A8: Reference Case | B8: South Atlantic | C8: 1.544 | D8: 1.671 | E8: 2.04285 | F8: 1.88271 | G8: 1.89625 | H8: 2.3301 | I8: 2.46983 | J8: 2.47589 | K8: 2.535531 | L8: 2.790259 | M8: 2.768037 | N8: 2.468727 | O8: 2.605338 | P8: =1.0588*M8 -> 2.9307976 | Q8: 2.771119 | R8: 2.839481 | S8: 2.802256 | T8: 2.786452 | U8: 2.676992 | V8: 2.548651 | W8: 2.418587 | X8: 2.196743 | Y8: 2.304419 | Z8: 2.088257 | AA8: 1.92241 | AB8: 1.878592 | AC8: 1.926551 | AD8: 1.718812 | AE8: 1.718832 | AF8: 1.680835 | AG8: 1.617794 | AH8: 1.619307 | AI8: 1.598931 | AJ8: 1.554882 | AK8: 1.479005 | AL8: 1.469072 | AM8: 1.423282 | AN8: 1.39668 | AO8: 1.344266 | AP8: 1.313927 | AQ8: 1.359366
A9: Reference Case | B9: West North Central | C9: 0.124 | D9: 0.117 | E9: 0.17066 | F9: 0.13982 | G9: 0.10807 | H9: 0.14716 | I9: 0.19192 | J9: 0.17219 | K9: 0.189613 | L9: 0.228314 | M9: 0.247312 | N9: 0.195056 | O9: 0.257507 | P9: =1.0588*M9 -> 0.26185395 | Q9: 0.328229 | R9: 0.333078 | S9: 0.292994 | T9: 0.347046 | U9: 0.365627 | V9: 0.403164 | W9: 0.456933 | X9: 0.434738 | Y9: 0.589867 | Z9: 0.553112 | AA9: 0.410186 | AB9: 0.37401 | AC9: 0.346125 | AD9: 0.332811 | AE9: 0.307617 | AF9: 0.271675 | AG9: 0.272217 | AH9: 0.285775 | AI9: 0.264481 | AJ9: 0.265405 | AK9: 0.239437 | AL9: 0.278295 | AM9: 0.288586 | AN9: 0.303452 | AO9: 0.320825 | AP9: 0.320191 | AQ9: 0.331866
A10: Reference Case | B10: West South Central | C10: 2.049 | D10: 2.188 | E10: 2.33724 | F10: 2.07546 | G10: 2.02567 | H10: 2.43411 | I10: 2.35184 | J10: 2.06317 | K10: 2.661307 | L10: 2.928261 | M10: 2.940385 | N10: 2.73224 | O10: 2.797009 | P10: =1.0588*M10 -> 3.1132796 | Q10: 3.278091 | R10: 3.062861 | S10: 2.831672 | T10: 2.92258 | U10: 2.856328 | V10: 2.763967 | W10: 2.771827 | X10: 2.681658 | Y10: 2.831487 | Z10: 2.650223 | AA10: 2.548273 | AB10: 2.161885 | AC10: 1.876698 | AD10: 1.742069 | AE10: 1.661109 | AF10: 1.621889 | AG10: 1.688687 | AH10: 1.746875 | AI10: 1.757097 | AJ10: 1.737841 | AK10: 1.767898 | AL10: 1.725534 | AM10: 1.73741 | AN10: 1.77373 | AO10: 1.755996 | AP10: 1.718013 | AQ10: 1.536503
A11: Reference Case | B11: Total | C11: 7.55 | D11: 7.76 | E11: 9.31283 | F11: 8.35984 | G11: 8.38063 | H11: 9.96951 | I11: 10.30898 | J11: 9.53121 | K11: 10.744287 | L11: 11.774796 | M11: 12.113228 | N11: 11.228085 | O11: 12.201015 | P11: =1.0588*M11 -> 12.825486 | Q11: 13.930565 | R11: 13.095462 | S11: 12.439513 | T11: 12.803668 | U11: 12.693147 | V11: 12.668743 | W11: 12.698741 | X11: 12.293569 | Y11: 13.498645 | Z11: 12.521386 | AA11: 11.60011 | AB11: 10.933743 | AC11: 10.342373 | AD11: 9.461121 | AE11: 8.895297 | AF11: 8.573374 | AG11: 8.630405 | AH11: 8.815576 | AI11: 8.765024 | AJ11: 8.842443 | AK11: 8.886514 | AL11: 8.882309 | AM11: 8.847266 | AN11: 8.788872 | AO11: 8.813865 | AP11: 8.752841 | AQ11: 8.663244
A12: High O&G Resource | B12: East North Central | C12: 0.326 | D12: 0.395 | E12: 0.6556 | F12: 0.4753 | G12: 0.48286 | H12: 0.71331 | I12: 0.91214 | J12: 0.81026 | K12: 1.00257 | L12: 1.185716 | M12: 1.262778 | N12: 1.082247 | O12: 1.477695 | P12: =1.0588*M12 -> 1.3370293 | Q12: 1.807217 | R12: 1.721987 | S12: 2.042994 | T12: 2.206338 | U12: 2.334784 | V12: 2.512054 | W12: 2.602928 | X12: 2.751464 | Y12: 3.253971 | Z12: 3.23993 | AA12: 3.205562 | AB12: 3.212188 | AC12: 3.132051 | AD12: 3.140409 | AE12: 2.716094 | AF12: 2.581804 | AG12: 2.550396 | AH12: 2.603838 | AI12: 2.774909 | AJ12: 2.887747 | AK12: 2.989638 | AL12: 3.06196 | AM12: 3.099662 | AN12: 2.97911 | AO12: 2.855375 | AP12: 2.984837 | AQ12: 2.927017
A13: High O&G Resource | B13: East South Central | C13: 0.567 | D13: 0.639 | E13: 0.7973 | F13: 0.62896 | G13: 0.67191 | H13: 0.87542 | I13: 0.9619 | J13: 0.9109 | K13: 0.994602 | L13: 1.029824 | M13: 1.047204 | N13: 0.913914 | O13: 0.90048 | P13: =1.0588*M13 -> 1.1087796 | Q13: 1.120767 | R13: 1.101454 | S13: 1.240576 | T13: 1.345413 | U13: 1.306726 | V13: 1.324362 | W13: 1.24977 | X13: 1.181122 | Y13: 1.202948 | Z13: 1.22631 | AA13: 1.228781 | AB13: 1.185304 | AC13: 1.137773 | AD13: 1.144755 | AE13: 1.158549 | AF13: 1.105213 | AG13: 1.084304 | AH13: 1.106517 | AI13: 1.088461 | AJ13: 1.150788 | AK13: 1.153446 | AL13: 1.184258 | AM13: 1.255747 | AN13: 1.305926 | AO13: 1.313169 | AP13: 1.298944 | AQ13: 1.317363
A14: High O&G Resource | B14: Middle Atlantic | C14: 0.89 | D14: 0.965 | E14: 1.15412 | F14: 1.06634 | G14: 1.13148 | H14: 1.23645 | I14: 1.3445 | J14: 1.19616 | K14: 1.300064 | L14: 1.451554 | M14: 1.684218 | N14: 1.654776 | O14: 1.998293 | P14: =1.0588*M14 -> 1.78325 | Q14: 1.951789 | R14: 1.590906 | S14: 1.697816 | T14: 1.701938 | U14: 1.644293 | V14: 1.630497 | W14: 1.778863 | X14: 1.787377 | Y14: 1.845946 | Z14: 1.84822 | AA14: 1.843454 | AB14: 1.710656 | AC14: 1.642419 | AD14: 1.6444 | AE14: 1.590891 | AF14: 1.437783 | AG14: 1.440836 | AH14: 1.471445 | AI14: 1.400841 | AJ14: 1.453301 | AK14: 1.539554 | AL14: 1.580606 | AM14: 1.648451 | AN14: 1.739527 | AO14: 1.745558 | AP14: 1.680766 | AQ14: 1.685399
A15: High O&G Resource | B15: Mountain | C15: 0.641 | D15: 0.567 | E15: 0.66283 | F15: 0.65072 | G15: 0.64891 | H15: 0.75092 | I15: 0.76576 | J15: 0.69033 | K15: 0.760259 | L15: 0.988215 | M15: 0.954761 | N15: 0.947247 | O15: 0.947744 | P15: =1.0588*M15 -> 1.0109009 | Q15: 1.198553 | R15: 1.094271 | S15: 1.131739 | T15: 1.092678 | U15: 1.079716 | V15: 1.073624 | W15: 1.176084 | X15: 1.214582 | Y15: 1.326644 | Z15: 1.274809 | AA15: 1.246807 | AB15: 1.19792 | AC15: 1.329532 | AD15: 1.32666 | AE15: 1.171483 | AF15: 1.016782 | AG15: 1.072407 | AH15: 1.044572 | AI15: 1.070091 | AJ15: 1.107367 | AK15: 1.171576 | AL15: 1.259128 | AM15: 1.248391 | AN15: 1.285874 | AO15: 1.325776 | AP15: 1.364214 | AQ15: 1.45559
A16: High O&G Resource | B16: New England | C16: 0.42 | D16: 0.456 | E16: 0.44768 | F16: 0.37155 | G16: 0.34175 | H16: 0.39761 | I16: 0.39318 | J16: 0.37141 | K16: 0.400407 | L16: 0.338651 | M16: 0.360853 | N16: 0.344592 | O16: 0.366773 | P16: 0.38207116 | Q16: 0.446506 | R16: 0.400232 | S16: 0.311662 | T16: 0.26856 | U16: 0.244934 | V16: 0.241361 | W16: 0.196057 | X16: 0.174589 | Y16: 0.193283 | Z16: 0.18547 | AA16: 0.187396 | AB16: 0.192078 | AC16: 0.1997 | AD16: 0.206521 | AE16: 0.197384 | AF16: 0.185696 | AG16: 0.1913 | AH16: 0.196422 | AI16: 0.208031 | AJ16: 0.215927 | AK16: 0.195102 | AL16: 0.159384 | AM16: 0.161159 | AN16: 0.167061 | AO16: 0.168816 | AP16: 0.16795 | AQ16: 0.15661
A17: High O&G Resource | B17: Pacific | C17: 0.989 | D17: 0.766 | E17: 1.04455 | F17: 1.06898 | G17: 1.07373 | H17: 1.08443 | I17: 0.91791 | J17: 0.8409 | K17: 0.871735 | L17: 0.834003 | M17: 0.847681 | N17: 0.887034 | O17: 0.850175 | P17: =1.0588*M17 -> 0.89752464 | Q17: 1.01817 | R17: 0.854088 | S17: 0.761514 | T17: 0.750901 | U17: 0.78061 | V17: 0.828471 | W17: 0.901304 | X17: 0.966842 | Y17: 1.003485 | Z17: 1.094409 | AA17: 1.119302 | AB17: 1.137609 | AC17: 1.008565 | AD17: 1.047966 | AE17: 1.034278 | AF17: 1.041979 | AG17: 1.048653 | AH17: 1.087787 | AI17: 1.072913 | AJ17: 1.04736 | AK17: 1.045559 | AL17: 1.036926 | AM17: 1.04817 | AN17: 1.030689 | AO17: 1.004289 | AP17: 1.004726 | AQ17: 0.990377
A18: High O&G Resource | B18: South Atlantic | C18: 1.544 | D18: 1.671 | E18: 2.04285 | F18: 1.88271 | G18: 1.89625 | H18: 2.3301 | I18: 2.46983 | J18: 2.47589 | K18: 2.535531 | L18: 2.790259 | M18: 2.768037 | N18: 2.468727 | O18: 2.605338 | P18: =1.0588*M18 -> 2.9307976 | Q18: 2.772431 | R18: 2.802444 | S18: 2.951403 | T18: 3.033981 | U18: 3.01577 | V18: 2.969723 | W18: 2.868471 | X18: 2.69715 | Y18: 2.864202 | Z18: 2.768513 | AA18: 2.743542 | AB18: 2.655394 | AC18: 2.550056 | AD18: 2.471244 | AE18: 2.439109 | AF18: 2.377795 | AG18: 2.49518 | AH18: 2.572892 | AI18: 2.560002 | AJ18: 2.60474 | AK18: 2.585567 | AL18: 2.56146 | AM18: 2.573675 | AN18: 2.549114 | AO18: 2.529676 | AP18: 2.625262 | AQ18: 2.632061
A19: High O&G Resource | B19: West North Central | C19: 0.124 | D19: 0.117 | E19: 0.17066 | F19: 0.13982 | G19: 0.10807 | H19: 0.14716 | I19: 0.19192 | J19: 0.17219 | K19: 0.189613 | L19: 0.228314 | M19: 0.247312 | N19: 0.195056 | O19: 0.257507 | P19: =1.0588*M19 -> 0.26185395 | Q19: 0.328414 | R19: 0.31658 | S19: 0.339554 | T19: 0.389654 | U19: 0.37641 | V19: 0.398223 | W19: 0.427727 | X19: 0.491814 | Y19: 0.599109 | Z19: 0.497179 | AA19: 0.490385 | AB19: 0.484944 | AC19: 0.420684 | AD19: 0.416561 | AE19: 0.376668 | AF19: 0.354041 | AG19: 0.359027 | AH19: 0.366828 | AI19: 0.382864 | AJ19: 0.405494 | AK19: 0.4108 | AL19: 0.439917 | AM19: 0.463651 | AN19: 0.46623 | AO19: 0.474269 | AP19: 0.425213 | AQ19: 0.381755
A20: High O&G Resource | B20: West South Central | C20: 2.049 | D20: 2.188 | E20: 2.33724 | F20: 2.07546 | G20: 2.02567 | H20: 2.43411 | I20: 2.35184 | J20: 2.06317 | K20: 2.661307 | L20: 2.928261 | M20: 2.940385 | N20: 2.73224 | O20: 2.797009 | P20: =1.0588*M20 -> 3.1132796 | Q20: 3.282638 | R20: 3.123186 | S20: 3.375084 | T20: 3.394222 | U20: 3.293242 | V20: 3.188257 | W20: 3.24422 | X20: 3.251625 | Y20: 3.415374 | Z20: 3.408022 | AA20: 3.36646 | AB20: 3.317858 | AC20: 2.939176 | AD20: 2.535467 | AE20: 2.472733 | AF20: 2.369297 | AG20: 2.332093 | AH20: 2.428086 | AI20: 2.434259 | AJ20: 2.535568 | AK20: 2.570477 | AL20: 2.601221 | AM20: 2.629858 | AN20: 2.650514 | AO20: 2.607504 | AP20: 2.676126 | AQ20: 2.65857
A21: High O&G Resource | B21: Total | C21: 7.55 | D21: 7.76 | E21: 9.31283 | F21: 8.35984 | G21: 8.38063 | H21: 9.96951 | I21: 10.30898 | J21: 9.53121 | K21: 10.744287 | L21: 11.774796 | M21: 12.113228 | N21: 11.228085 | O21: 12.201015 | P21: =1.0588*M21 -> 12.825486 | Q21: 13.926487 | R21: 13.005149 | S21: 13.852345 | T21: 14.183685 | U21: 14.076487 | V21: 14.166571 | W21: 14.445424 | X21: 14.516565 | Y21: 15.704962 | Z21: 15.542862 | AA21: 15.431691 | AB21: 15.093952 | AC21: 14.359958 | AD21: 13.933985 | AE21: 13.157188 | AF21: 12.470389 | AG21: 12.574196 | AH21: 12.878387 | AI21: 12.99237 | AJ21: 13.408292 | AK21: 13.661719 | AL21: 13.884859 | AM21: 14.128766 | AN21: 14.174046 | AO21: 14.02443 | AP21: 14.228036 | AQ21: 14.204741
A22: Low O&G Resource | B22: East North Central | C22: 0.326 | D22: 0.395 | E22: 0.6556 | F22: 0.4753 | G22: 0.48286 | H22: 0.71331 | I22: 0.91214 | J22: 0.81026 | K22: 1.00257 | L22: 1.185716 | M22: 1.262778 | N22: 1.082247 | O22: 1.477695 | P22: =1.0588*M22 -> 1.3370293 | Q22: 1.804559 | R22: 1.74832 | S22: 1.402841 | T22: 1.498055 | U22: 1.509668 | V22: 1.496857 | W22: 1.534067 | X22: 1.384653 | Y22: 1.565061 | Z22: 1.333007 | AA22: 1.233128 | AB22: 1.111427 | AC22: 1.031229 | AD22: 0.854965 | AE22: 0.732474 | AF22: 0.758101 | AG22: 0.698537 | AH22: 0.664124 | AI22: 0.615075 | AJ22: 0.606697 | AK22: 0.587082 | AL22: 0.607441 | AM22: 0.663438 | AN22: 0.687064 | AO22: 0.734405 | AP22: 0.789578 | AQ22: 0.816287
A23: Low O&G Resource | B23: East South Central | C23: 0.567 | D23: 0.639 | E23: 0.7973 | F23: 0.62896 | G23: 0.67191 | H23: 0.87542 | I23: 0.9619 | J23: 0.9109 | K23: 0.994602 | L23: 1.029824 | M23: 1.047204 | N23: 0.913914 | O23: 0.90048 | P23: =1.0588*M23 -> 1.1087796 | Q23: 1.12185 | R23: 1.053865 | S23: 0.872166 | T23: 0.930938 | U23: 0.907154 | V23: 0.871673 | W23: 0.808875 | X23: 0.668381 | Y23: 0.734924 | Z23: 0.691406 | AA23: 0.634744 | AB23: 0.63708 | AC23: 0.549481 | AD23: 0.48277 | AE23: 0.435245 | AF23: 0.374653 | AG23: 0.296413 | AH23: 0.238602 | AI23: 0.237566 | AJ23: 0.257154 | AK23: 0.247615 | AL23: 0.218179 | AM23: 0.209494 | AN23: 0.198955 | AO23: 0.201429 | AP23: 0.213645 | AQ23: 0.2179
A24: Low O&G Resource | B24: Middle Atlantic | C24: 0.89 | D24: 0.965 | E24: 1.15412 | F24: 1.06634 | G24: 1.13148 | H24: 1.23645 | I24: 1.3445 | J24: 1.19616 | K24: 1.300064 | L24: 1.451554 | M24: 1.684218 | N24: 1.654776 | O24: 1.998293 | P24: =1.0588*M24 -> 1.78325 | Q24: 1.954733 | R24: 1.720835 | S24: 1.49083 | T24: 1.4678 | U24: 1.385326 | V24: 1.412108 | W24: 1.373499 | X24: 1.197684 | Y24: 1.132102 | Z24: 1.060135 | AA24: 0.929961 | AB24: 0.89326 | AC24: 0.788534 | AD24: 0.586714 | AE24: 0.522783 | AF24: 0.54963 | AG24: 0.527879 | AH24: 0.488661 | AI24: 0.463385 | AJ24: 0.473387 | AK24: 0.474389 | AL24: 0.444759 | AM24: 0.450912 | AN24: 0.450285 | AO24: 0.473709 | AP24: 0.480987 | AQ24: 0.472205
A25: Low O&G Resource | B25: Mountain | C25: 0.641 | D25: 0.567 | E25: 0.66283 | F25: 0.65072 | G25: 0.64891 | H25: 0.75092 | I25: 0.76576 | J25: 0.69033 | K25: 0.760259 | L25: 0.988215 | M25: 0.954761 | N25: 0.947247 | O25: 0.947744 | P25: =1.0588*M25 -> 1.0109009 | Q25: 1.202133 | R25: 1.072385 | S25: 0.829442 | T25: 0.809352 | U25: 0.783828 | V25: 0.776658 | W25: 0.770984 | X25: 0.692458 | Y25: 0.847123 | Z25: 0.82023 | AA25: 0.759908 | AB25: 0.72217 | AC25: 0.65372 | AD25: 0.626503 | AE25: 0.52724 | AF25: 0.54579 | AG25: 0.509211 | AH25: 0.438115 | AI25: 0.395162 | AJ25: 0.383094 | AK25: 0.395633 | AL25: 0.407519 | AM25: 0.364727 | AN25: 0.383422 | AO25: 0.416587 | AP25: 0.453987 | AQ25: 0.48647
A26: Low O&G Resource | B26: New England | C26: 0.42 | D26: 0.456 | E26: 0.44768 | F26: 0.37155 | G26: 0.34175 | H26: 0.39761 | I26: 0.39318 | J26: 0.37141 | K26: 0.400407 | L26: 0.338651 | M26: 0.360853 | N26: 0.344592 | O26: 0.366773 | P26: 0.38207116 | Q26: 0.452001 | R26: 0.400253 | S26: 0.251434 | T26: 0.211858 | U26: 0.194398 | V26: 0.192247 | W26: 0.174559 | X26: 0.157962 | Y26: 0.176228 | Z26: 0.166235 | AA26: 0.1614 | AB26: 0.165505 | AC26: 0.162913 | AD26: 0.137538 | AE26: 0.132298 | AF26: 0.134267 | AG26: 0.136717 | AH26: 0.137923 | AI26: 0.13546 | AJ26: 0.138723 | AK26: 0.10313 | AL26: 0.087387 | AM26: 0.092547 | AN26: 0.092992 | AO26: 0.09381 | AP26: 0.095297 | AQ26: 0.096417
A27: Low O&G Resource | B27: Pacific | C27: 0.989 | D27: 0.766 | E27: 1.04455 | F27: 1.06898 | G27: 1.07373 | H27: 1.08443 | I27: 0.91791 | J27: 0.8409 | K27: 0.871735 | L27: 0.834003 | M27: 0.847681 | N27: 0.887034 | O27: 0.850175 | P27: =1.0588*M27 -> 0.89752464 | Q27: 1.018694 | R27: 0.786553 | S27: 0.687765 | T27: 0.664922 | U27: 0.704409 | V27: 0.741716 | W27: 0.772348 | X27: 0.789767 | Y27: 0.815216 | Z27: 0.797631 | AA27: 0.756096 | AB27: 0.688957 | AC27: 0.632692 | AD27: 0.554879 | AE27: 0.494092 | AF27: 0.454257 | AG27: 0.467174 | AH27: 0.449188 | AI27: 0.437638 | AJ27: 0.435116 | AK27: 0.442636 | AL27: 0.440998 | AM27: 0.441239 | AN27: 0.446543 | AO27: 0.465141 | AP27: 0.473856 | AQ27: 0.488408
A28: Low O&G Resource | B28: South Atlantic | C28: 1.544 | D28: 1.671 | E28: 2.04285 | F28: 1.88271 | G28: 1.89625 | H28: 2.3301 | I28: 2.46983 | J28: 2.47589 | K28: 2.535531 | L28: 2.790259 | M28: 2.768037 | N28: 2.468727 | O28: 2.605338 | P28: =1.0588*M28 -> 2.9307976 | Q28: 2.774692 | R28: 2.728033 | S28: 2.304525 | T28: 2.249545 | U28: 2.034196 | V28: 1.84641 | W28: 1.719123 | X28: 1.451879 | Y28: 1.585336 | Z28: 1.433254 | AA28: 1.357102 | AB28: 1.358099 | AC28: 1.24435 | AD28: 1.119637 | AE28: 1.064564 | AF28: 0.993744 | AG28: 0.974679 | AH28: 0.975145 | AI28: 0.974492 | AJ28: 0.925296 | AK28: 0.871767 | AL28: 0.779892 | AM28: 0.730188 | AN28: 0.693493 | AO28: 0.71479 | AP28: 0.700422 | AQ28: 0.698386
A29: Low O&G Resource | B29: West North Central | C29: 0.124 | D29: 0.117 | E29: 0.17066 | F29: 0.13982 | G29: 0.10807 | H29: 0.14716 | I29: 0.19192 | J29: 0.17219 | K29: 0.189613 | L29: 0.228314 | M29: 0.247312 | N29: 0.195056 | O29: 0.257507 | P29: =1.0588*M29 -> 0.26185395 | Q29: 0.33001 | R29: 0.311531 | S29: 0.199013 | T29: 0.238384 | U29: 0.246067 | V29: 0.27598 | W29: 0.437111 | X29: 0.358888 | Y29: 0.451031 | Z29: 0.368381 | AA29: 0.308266 | AB29: 0.275428 | AC29: 0.26154 | AD29: 0.271243 | AE29: 0.25409 | AF29: 0.266654 | AG29: 0.271079 | AH29: 0.224717 | AI29: 0.20615 | AJ29: 0.213672 | AK29: 0.236184 | AL29: 0.234486 | AM29: 0.237393 | AN29: 0.263399 | AO29: 0.265423 | AP29: 0.270487 | AQ29: 0.278686
A30: Low O&G Resource | B30: West South Central | C30: 2.049 | D30: 2.188 | E30: 2.33724 | F30: 2.07546 | G30: 2.02567 | H30: 2.43411 | I30: 2.35184 | J30: 2.06317 | K30: 2.661307 | L30: 2.928261 | M30: 2.940385 | N30: 2.73224 | O30: 2.797009 | P30: =1.0588*M30 -> 3.1132796 | Q30: 3.27164 | R30: 3.139995 | S30: 2.062922 | T30: 2.1327 | U30: 1.991213 | V30: 1.856138 | W30: 1.857033 | X30: 1.640671 | Y30: 1.789956 | Z30: 1.579497 | AA30: 1.513954 | AB30: 1.327169 | AC30: 1.226203 | AD30: 1.115833 | AE30: 1.057815 | AF30: 1.017851 | AG30: 1.049425 | AH30: 0.994796 | AI30: 0.978935 | AJ30: 0.991719 | AK30: 1.000719 | AL30: 1.004305 | AM30: 0.993623 | AN30: 1.0473 | AO30: 1.086109 | AP30: 1.095479 | AQ30: 1.125022
A31: Low O&G Resource | B31: Total | C31: 7.55 | D31: 7.76 | E31: 9.31283 | F31: 8.35984 | G31: 8.38063 | H31: 9.96951 | I31: 10.30898 | J31: 9.53121 | K31: 10.744287 | L31: 11.774796 | M31: 12.113228 | N31: 11.228085 | O31: 12.201015 | P31: =1.0588*M31 -> 12.825486 | Q31: 13.93031 | R31: 12.96177 | S31: 10.100938 | T31: 10.203553 | U31: 9.756258 | V31: 9.469786 | W31: 9.447601 | X31: 8.342342 | Y31: 9.096979 | Z31: 8.249777 | AA31: 7.654561 | AB31: 7.179094 | AC31: 6.550663 | AD31: 5.750082 | AE31: 5.220602 | AF31: 5.094946 | AG31: 4.931115 | AH31: 4.611271 | AI31: 4.443863 | AJ31: 4.424858 | AK31: 4.359155 | AL31: 4.224965 | AM31: 4.183562 | AN31: 4.263453 | AO31: 4.451402 | AP31: 4.573738 | AQ31: 4.67978

Sheet NG Alphas
C1: 0.602782 | D1: Convert from 2024$ to 2004$
C2: 0.13520853 | D2: National Beta (2004$/MMBtu per Quad of Demand) | AT2: Check
AT3: For 2040
A4: alphas are 2004$/MMBtu | C4: Regional Beta | D4: 2010 | E4: 2011 | F4: 2012 | G4: 2013 | H4: 2014 | I4: 2015 | J4: 2016 | K4: 2017 | L4: 2018 | M4: 2019 | N4: 2020 | O4: 2021 | P4: 2022 | Q4: 2023 | R4: 2024 | S4: 2025 | T4: 2026 | U4: 2027 | V4: 2028 | W4: 2029 | X4: 2030 | Y4: 2031 | Z4: 2032 | AA4: 2033 | AB4: 2034 | AC4: 2035 | AD4: 2036 | AE4: 2037 | AF4: 2038 | AG4: 2039 | AH4: 2040 | AI4: 2041 | AJ4: 2042 | AK4: 2043 | AL4: 2044 | AM4: 2045 | AN4: 2046 | AO4: 2047 | AP4: 2048 | AQ4: 2049 | AR4: 2050 | AT4: Calculated Price | AU4: AEO Price
A5: Reference Case | B5: East North Central | C5: 0.26295634 | D5: ='Prices by Case'!C2*$C$1 -> 4.2743239 | E5: ='Prices by Case'!D2*$C$1-'NG Alphas'!$C5*'Demand by Case'!D2-'NG Alphas'!$C$2*'Demand by Case'!D$11 -> 2.7139079 | F5: ='Prices by Case'!E2*$C$1-'NG Alphas'!$C5*'Demand by Case'!E2-'NG Alphas'!$C$2*'Demand by Case'!E$11 -> 1.1714833 | G5: ='Prices by Case'!F2*$C$1-'NG Alphas'!$C5*'Demand by Case'!F2-'NG Alphas'!$C$2*'Demand by Case'!F$11 -> 2.1471413 | H5: ='Prices by Case'!G2*$C$1-'NG Alphas'!$C5*'Demand by Case'!G2-'NG Alphas'!$C$2*'Demand by Case'!G$11 -> 2.9000407 | I5: ='Prices by Case'!H2*$C$1-'NG Alphas'!$C5*'Demand by Case'!H2-'NG Alphas'!$C$2*'Demand by Case'!H$11 -> 0.71192199 | J5: ='Prices by Case'!I2*$C$1-'NG Alphas'!$C5*'Demand by Case'!I2-'NG Alphas'!$C$2*'Demand by Case'!I$11 -> 0.53890978 | K5: ='Prices by Case'!J2*$C$1-'NG Alphas'!$C5*'Demand by Case'!J2-'NG Alphas'!$C$2*'Demand by Case'!J$11 -> 1.0608623 | L5: ='Prices by Case'!K2*$C$1-'NG Alphas'!$C5*'Demand by Case'!K2-'NG Alphas'!$C$2*'Demand by Case'!K$11 -> 0.74484405 | ... AR5: ='Prices by Case'!AQ2*$C$1-'NG Alphas'!$C5*'Demand by Case'!AQ2-'NG Alphas'!$C$2*'Demand by Case'!AQ$11 -> 0.59676825 | AT5: =(AH5+'Demand by Case'!AG2*'NG Alphas'!C5+'Demand by Case'!$AG$11*'NG Alphas'!$C$2)/'NG Alphas'!$C$1 -> 3.662889 | AU5: 5.585239
A6: Reference Case | B6: East South Central | C6: 0.60841227 | D6: ='Prices by Case'!C3*$C$1 -> 4.1378736 | E6: ='Prices by Case'!D3*$C$1-'NG Alphas'!$C6*'Demand by Case'!D3-'NG Alphas'!$C$2*'Demand by Case'!D$11 -> 2.2002798 | F6: ='Prices by Case'!E3*$C$1-'NG Alphas'!$C6*'Demand by Case'!E3-'NG Alphas'!$C$2*'Demand by Case'!E$11 -> 0.77014557 | G6: ='Prices by Case'!F3*$C$1-'NG Alphas'!$C6*'Demand by Case'!F3-'NG Alphas'!$C$2*'Demand by Case'!F$11 -> 1.7575023 | H6: ='Prices by Case'!G3*$C$1-'NG Alphas'!$C6*'Demand by Case'!G3-'NG Alphas'!$C$2*'Demand by Case'!G$11 -> 2.1929869 | I6: ='Prices by Case'!H3*$C$1-'NG Alphas'!$C6*'Demand by Case'!H3-'NG Alphas'!$C$2*'Demand by Case'!H$11 -> 0.429196 | J6: ='Prices by Case'!I3*$C$1-'NG Alphas'!$C6*'Demand by Case'!I3-'NG Alphas'!$C$2*'Demand by Case'!I$11 -> 0.039588121 | K6: ='Prices by Case'!J3*$C$1-'NG Alphas'!$C6*'Demand by Case'!J3-'NG Alphas'!$C$2*'Demand by Case'!J$11 -> 0.60453658 | L6: ='Prices by Case'!K3*$C$1-'NG Alphas'!$C6*'Demand by Case'!K3-'NG Alphas'!$C$2*'Demand by Case'!K$11 -> 0.3689439 | ... AR6: ='Prices by Case'!AQ3*$C$1-'NG Alphas'!$C6*'Demand by Case'!AQ3-'NG Alphas'!$C$2*'Demand by Case'!AQ$11 -> 0.99016899 | AT6: =(AH6+'Demand by Case'!AG3*'NG Alphas'!C6+'Demand by Case'!$AG$11*'NG Alphas'!$C$2)/'NG Alphas'!$C$1 -> 4.299133 | AU6: 5.029574
A7: Reference Case | B7: Middle Atlantic | C7: 0.14497775 | D7: ='Prices by Case'!C4*$C$1 -> 4.7115638 | E7: ='Prices by Case'!D4*$C$1-'NG Alphas'!$C7*'Demand by Case'!D4-'NG Alphas'!$C$2*'Demand by Case'!D$11 -> 3.1398234 | F7: ='Prices by Case'!E4*$C$1-'NG Alphas'!$C7*'Demand by Case'!E4-'NG Alphas'!$C$2*'Demand by Case'!E$11 -> 1.5397672 | G7: ='Prices by Case'!F4*$C$1-'NG Alphas'!$C7*'Demand by Case'!F4-'NG Alphas'!$C$2*'Demand by Case'!F$11 -> 2.465455 | H7: ='Prices by Case'!G4*$C$1-'NG Alphas'!$C7*'Demand by Case'!G4-'NG Alphas'!$C$2*'Demand by Case'!G$11 -> 2.7714772 | I7: ='Prices by Case'!H4*$C$1-'NG Alphas'!$C7*'Demand by Case'!H4-'NG Alphas'!$C$2*'Demand by Case'!H$11 -> 0.79368306 | J7: ='Prices by Case'!I4*$C$1-'NG Alphas'!$C7*'Demand by Case'!I4-'NG Alphas'!$C$2*'Demand by Case'!I$11 -> 0.61804108 | K7: ='Prices by Case'!J4*$C$1-'NG Alphas'!$C7*'Demand by Case'!J4-'NG Alphas'!$C$2*'Demand by Case'!J$11 -> 1.0452689 | L7: ='Prices by Case'!K4*$C$1-'NG Alphas'!$C7*'Demand by Case'!K4-'NG Alphas'!$C$2*'Demand by Case'!K$11 -> 0.90758109 | ... AR7: ='Prices by Case'!AQ4*$C$1-'NG Alphas'!$C7*'Demand by Case'!AQ4-'NG Alphas'!$C$2*'Demand by Case'!AQ$11 -> 0.53960154 | AT7: =(AH7+'Demand by Case'!AG4*'NG Alphas'!C7+'Demand by Case'!$AG$11*'NG Alphas'!$C$2)/'NG Alphas'!$C$1 -> 3.215503 | AU7: 5.750043
A8: Reference Case | B8: Mountain | C8: 0.54532052 | D8: ='Prices by Case'!C5*$C$1 -> 4.348851 | E8: ='Prices by Case'!D5*$C$1-'NG Alphas'!$C8*'Demand by Case'!D5-'NG Alphas'!$C$2*'Demand by Case'!D$11 -> 2.7158125 | F8: ='Prices by Case'!E5*$C$1-'NG Alphas'!$C8*'Demand by Case'!E5-'NG Alphas'!$C$2*'Demand by Case'!E$11 -> 1.2803754 | G8: ='Prices by Case'!F5*$C$1-'NG Alphas'!$C8*'Demand by Case'!F5-'NG Alphas'!$C$2*'Demand by Case'!F$11 -> 2.1476221 | H8: ='Prices by Case'!G5*$C$1-'NG Alphas'!$C8*'Demand by Case'!G5-'NG Alphas'!$C$2*'Demand by Case'!G$11 -> 2.4511279 | I8: ='Prices by Case'!H5*$C$1-'NG Alphas'!$C8*'Demand by Case'!H5-'NG Alphas'!$C$2*'Demand by Case'!H$11 -> 0.82455363 | J8: ='Prices by Case'!I5*$C$1-'NG Alphas'!$C8*'Demand by Case'!I5-'NG Alphas'!$C$2*'Demand by Case'!I$11 -> 0.32504394 | K8: ='Prices by Case'!J5*$C$1-'NG Alphas'!$C8*'Demand by Case'!J5-'NG Alphas'!$C$2*'Demand by Case'!J$11 -> 0.86366943 | L8: ='Prices by Case'!K5*$C$1-'NG Alphas'!$C8*'Demand by Case'!K5-'NG Alphas'!$C$2*'Demand by Case'!K$11 -> 0.73171209 | ... AR8: ='Prices by Case'!AQ5*$C$1-'NG Alphas'!$C8*'Demand by Case'!AQ5-'NG Alphas'!$C$2*'Demand by Case'!AQ$11 -> 1.8631046 | AT8: =(AH8+'Demand by Case'!AG5*'NG Alphas'!C8+'Demand by Case'!$AG$11*'NG Alphas'!$C$2)/'NG Alphas'!$C$1 -> 5.306404 | AU8: 5.961182
A9: Reference Case | B9: New England | C9: 0.5021758 | D9: ='Prices by Case'!C6*$C$1 -> 4.683875 | E9: ='Prices by Case'!D6*$C$1-'NG Alphas'!$C9*'Demand by Case'!D6-'NG Alphas'!$C$2*'Demand by Case'!D$11 -> 2.9271621 | F9: ='Prices by Case'!E6*$C$1-'NG Alphas'!$C9*'Demand by Case'!E6-'NG Alphas'!$C$2*'Demand by Case'!E$11 -> 1.6056841 | G9: ='Prices by Case'!F6*$C$1-'NG Alphas'!$C9*'Demand by Case'!F6-'NG Alphas'!$C$2*'Demand by Case'!F$11 -> 3.5464152 | H9: ='Prices by Case'!G6*$C$1-'NG Alphas'!$C9*'Demand by Case'!G6-'NG Alphas'!$C$2*'Demand by Case'!G$11 -> 3.9811656 | I9: ='Prices by Case'!H6*$C$1-'NG Alphas'!$C9*'Demand by Case'!H6-'NG Alphas'!$C$2*'Demand by Case'!H$11 -> 1.8666084 | J9: ='Prices by Case'!I6*$C$1-'NG Alphas'!$C9*'Demand by Case'!I6-'NG Alphas'!$C$2*'Demand by Case'!I$11 -> 1.5119946 | K9: ='Prices by Case'!J6*$C$1-'NG Alphas'!$C9*'Demand by Case'!J6-'NG Alphas'!$C$2*'Demand by Case'!J$11 -> 1.7528551 | L9: ='Prices by Case'!K6*$C$1-'NG Alphas'!$C9*'Demand by Case'!K6-'NG Alphas'!$C$2*'Demand by Case'!K$11 -> 1.89132 | ... AR9: ='Prices by Case'!AQ6*$C$1-'NG Alphas'!$C9*'Demand by Case'!AQ6-'NG Alphas'!$C$2*'Demand by Case'!AQ$11 -> 1.0291186 | AT9: =(AH9+'Demand by Case'!AG6*'NG Alphas'!C9+'Demand by Case'!$AG$11*'NG Alphas'!$C$2)/'NG Alphas'!$C$1 -> 3.872509 | AU9: 6.14927
A10: Reference Case | B10: Pacific | C10: 0.1968425 | D10: ='Prices by Case'!C7*$C$1 -> 4.1725022 | E10: ='Prices by Case'!D7*$C$1-'NG Alphas'!$C10*'Demand by Case'!D7-'NG Alphas'!$C$2*'Demand by Case'!D$11 -> 2.7320029 | F10: ='Prices by Case'!E7*$C$1-'NG Alphas'!$C10*'Demand by Case'!E7-'NG Alphas'!$C$2*'Demand by Case'!E$11 -> 1.5382517 | G10: ='Prices by Case'!F7*$C$1-'NG Alphas'!$C10*'Demand by Case'!F7-'NG Alphas'!$C$2*'Demand by Case'!F$11 -> 2.2558133 | H10: ='Prices by Case'!G7*$C$1-'NG Alphas'!$C10*'Demand by Case'!G7-'NG Alphas'!$C$2*'Demand by Case'!G$11 -> 2.665739 | I10: ='Prices by Case'!H7*$C$1-'NG Alphas'!$C10*'Demand by Case'!H7-'NG Alphas'!$C$2*'Demand by Case'!H$11 -> 1.0415252 | J10: ='Prices by Case'!I7*$C$1-'NG Alphas'!$C10*'Demand by Case'!I7-'NG Alphas'!$C$2*'Demand by Case'!I$11 -> 0.63590778 | K10: ='Prices by Case'!J7*$C$1-'NG Alphas'!$C10*'Demand by Case'!J7-'NG Alphas'!$C$2*'Demand by Case'!J$11 -> 1.0709235 | L10: ='Prices by Case'!K7*$C$1-'NG Alphas'!$C10*'Demand by Case'!K7-'NG Alphas'!$C$2*'Demand by Case'!K$11 -> 0.97809027 | ... AR10: ='Prices by Case'!AQ7*$C$1-'NG Alphas'!$C10*'Demand by Case'!AQ7-'NG Alphas'!$C$2*'Demand by Case'!AQ$11 -> 2.1698562 | AT10: =(AH10+'Demand by Case'!AG7*'NG Alphas'!C10+'Demand by Case'!$AG$11*'NG Alphas'!$C$2)/'NG Alphas'!$C$1 -> 5.055543 | AU10: 5.308188
A11: Reference Case | B11: South Atlantic | C11: 0.16186349 | D11: ='Prices by Case'!C8*$C$1 -> 5.2114045 | E11: ='Prices by Case'!D8*$C$1-'NG Alphas'!$C11*'Demand by Case'!D8-'NG Alphas'!$C$2*'Demand by Case'!D$11 -> 3.2690963 | F11: ='Prices by Case'!E8*$C$1-'NG Alphas'!$C11*'Demand by Case'!E8-'NG Alphas'!$C$2*'Demand by Case'!E$11 -> 1.8726286 | G11: ='Prices by Case'!F8*$C$1-'NG Alphas'!$C11*'Demand by Case'!F8-'NG Alphas'!$C$2*'Demand by Case'!F$11 -> 2.4758235 | H11: ='Prices by Case'!G8*$C$1-'NG Alphas'!$C11*'Demand by Case'!G8-'NG Alphas'!$C$2*'Demand by Case'!G$11 -> 2.910621 | I11: ='Prices by Case'!H8*$C$1-'NG Alphas'!$C11*'Demand by Case'!H8-'NG Alphas'!$C$2*'Demand by Case'!H$11 -> 1.4151553 | J11: ='Prices by Case'!I8*$C$1-'NG Alphas'!$C11*'Demand by Case'!I8-'NG Alphas'!$C$2*'Demand by Case'!I$11 -> 0.92748952 | K11: ='Prices by Case'!J8*$C$1-'NG Alphas'!$C11*'Demand by Case'!J8-'NG Alphas'!$C$2*'Demand by Case'!J$11 -> 1.247641 | L11: ='Prices by Case'!K8*$C$1-'NG Alphas'!$C11*'Demand by Case'!K8-'NG Alphas'!$C$2*'Demand by Case'!K$11 -> 0.96584 | ... AR11: ='Prices by Case'!AQ8*$C$1-'NG Alphas'!$C11*'Demand by Case'!AQ8-'NG Alphas'!$C$2*'Demand by Case'!AQ$11 -> 1.3686402 | AT11: =(AH11+'Demand by Case'!AG8*'NG Alphas'!C11+'Demand by Case'!$AG$11*'NG Alphas'!$C$2)/'NG Alphas'!$C$1 -> 4.854046 | AU11: 5.039312
A12: Reference Case | B12: West North Central | C12: 0.57865436 | D12: ='Prices by Case'!C9*$C$1 -> 4.6620898 | E12: ='Prices by Case'!D9*$C$1-'NG Alphas'!$C12*'Demand by Case'!D9-'NG Alphas'!$C$2*'Demand by Case'!D$11 -> 3.215774 | F12: ='Prices by Case'!E9*$C$1-'NG Alphas'!$C12*'Demand by Case'!E9-'NG Alphas'!$C$2*'Demand by Case'!E$11 -> 1.5577101 | G12: ='Prices by Case'!F9*$C$1-'NG Alphas'!$C12*'Demand by Case'!F9-'NG Alphas'!$C$2*'Demand by Case'!F$11 -> 2.5365061 | H12: ='Prices by Case'!G9*$C$1-'NG Alphas'!$C12*'Demand by Case'!G9-'NG Alphas'!$C$2*'Demand by Case'!G$11 -> 3.2640844 | I12: ='Prices by Case'!H9*$C$1-'NG Alphas'!$C12*'Demand by Case'!H9-'NG Alphas'!$C$2*'Demand by Case'!H$11 -> 1.2361317 | J12: ='Prices by Case'!I9*$C$1-'NG Alphas'!$C12*'Demand by Case'!I9-'NG Alphas'!$C$2*'Demand by Case'!I$11 -> 0.60506472 | K12: ='Prices by Case'!J9*$C$1-'NG Alphas'!$C12*'Demand by Case'!J9-'NG Alphas'!$C$2*'Demand by Case'!J$11 -> 1.3057929 | L12: ='Prices by Case'!K9*$C$1-'NG Alphas'!$C12*'Demand by Case'!K9-'NG Alphas'!$C$2*'Demand by Case'!K$11 -> 1.0502648 | ... AR12: ='Prices by Case'!AQ9*$C$1-'NG Alphas'!$C12*'Demand by Case'!AQ9-'NG Alphas'!$C$2*'Demand by Case'!AQ$11 -> 1.5250619 | AT12: =(AH12+'Demand by Case'!AG9*'NG Alphas'!C12+'Demand by Case'!$AG$11*'NG Alphas'!$C$2)/'NG Alphas'!$C$1 -> 4.491251 | AU12: 5.011335
A13: Reference Case | B13: West South Central | C13: 0.084871962 | D13: ='Prices by Case'!C10*$C$1 -> 3.986708 | E13: ='Prices by Case'!D10*$C$1-'NG Alphas'!$C13*'Demand by Case'!D10-'NG Alphas'!$C$2*'Demand by Case'!D$11 -> 2.3949954 | F13: ='Prices by Case'!E10*$C$1-'NG Alphas'!$C13*'Demand by Case'!E10-'NG Alphas'!$C$2*'Demand by Case'!E$11 -> 1.005573 | G13: ='Prices by Case'!F10*$C$1-'NG Alphas'!$C13*'Demand by Case'!F10-'NG Alphas'!$C$2*'Demand by Case'!F$11 -> 1.8953423 | H13: ='Prices by Case'!G10*$C$1-'NG Alphas'!$C13*'Demand by Case'!G10-'NG Alphas'!$C$2*'Demand by Case'!G$11 -> 2.3971762 | I13: ='Prices by Case'!H10*$C$1-'NG Alphas'!$C13*'Demand by Case'!H10-'NG Alphas'!$C$2*'Demand by Case'!H$11 -> 0.68153451 | J13: ='Prices by Case'!I10*$C$1-'NG Alphas'!$C13*'Demand by Case'!I10-'NG Alphas'!$C$2*'Demand by Case'!I$11 -> 0.27363173 | K13: ='Prices by Case'!J10*$C$1-'NG Alphas'!$C13*'Demand by Case'!J10-'NG Alphas'!$C$2*'Demand by Case'!J$11 -> 0.83540981 | L13: ='Prices by Case'!K10*$C$1-'NG Alphas'!$C13*'Demand by Case'!K10-'NG Alphas'!$C$2*'Demand by Case'!K$11 -> 0.60267473 | ... AR13: ='Prices by Case'!AQ10*$C$1-'NG Alphas'!$C13*'Demand by Case'!AQ10-'NG Alphas'!$C$2*'Demand by Case'!AQ$11 -> 1.6545384 | AT13: =(AH13+'Demand by Case'!AG10*'NG Alphas'!C13+'Demand by Case'!$AG$11*'NG Alphas'!$C$2)/'NG Alphas'!$C$1 -> 4.305593 | AU13: 5.139457
A14: Reference Case | B14: Total | C14: 0.16167811 | D14: ='Prices by Case'!C11*$C$1 -> 4.4779156 | E14: ='Prices by Case'!D11*'NG Alphas'!$C$1-'NG Alphas'!$C14*'Demand by Case'!D11 -> 2.7862634 | F14: ='Prices by Case'!E11*'NG Alphas'!$C$1-'NG Alphas'!$C14*'Demand by Case'!E11 -> 1.383384 | G14: ='Prices by Case'!F11*'NG Alphas'!$C$1-'NG Alphas'!$C14*'Demand by Case'!F11 -> 2.2634442 | H14: ='Prices by Case'!G11*'NG Alphas'!$C$1-'NG Alphas'!$C14*'Demand by Case'!G11 -> 2.7045387 | I14: ='Prices by Case'!H11*'NG Alphas'!$C$1-'NG Alphas'!$C14*'Demand by Case'!H11 -> 0.97271046 | J14: ='Prices by Case'!I11*'NG Alphas'!$C$1-'NG Alphas'!$C14*'Demand by Case'!I11 -> 0.59270812 | K14: ='Prices by Case'!J11*'NG Alphas'!$C$1-'NG Alphas'!$C14*'Demand by Case'!J11 -> 1.0665053 | L14: ='Prices by Case'!K11*'NG Alphas'!$C$1-'NG Alphas'!$C14*'Demand by Case'!K11 -> 0.83735634 | ... AR14: ='Prices by Case'!AQ11*'NG Alphas'!$C$1-'NG Alphas'!$C14*'Demand by Case'!AQ11 -> 1.2872487 | AT14: =(AH14+'Demand by Case'!AG11*'NG Alphas'!C14)/'NG Alphas'!$C$1 -> 4.309677 | AU14: 5.438611
A15: High O&G Resource | B15: East North Central | C15: 0.26295634 | D15: ='Prices by Case'!C12*$C$1 -> 4.2743239 | E15: ='Prices by Case'!D12*$C$1-'NG Alphas'!$C15*'Demand by Case'!D12-'NG Alphas'!$C$2*'Demand by Case'!D$11 -> 2.7139079 | F15: ='Prices by Case'!E12*$C$1-'NG Alphas'!$C15*'Demand by Case'!E12-'NG Alphas'!$C$2*'Demand by Case'!E$11 -> 1.1714833 | G15: ='Prices by Case'!F12*$C$1-'NG Alphas'!$C15*'Demand by Case'!F12-'NG Alphas'!$C$2*'Demand by Case'!F$11 -> 2.1471413 | H15: ='Prices by Case'!G12*$C$1-'NG Alphas'!$C15*'Demand by Case'!G12-'NG Alphas'!$C$2*'Demand by Case'!G$11 -> 2.9000407 | I15: ='Prices by Case'!H12*$C$1-'NG Alphas'!$C15*'Demand by Case'!H12-'NG Alphas'!$C$2*'Demand by Case'!H$11 -> 0.71192199 | J15: ='Prices by Case'!I12*$C$1-'NG Alphas'!$C15*'Demand by Case'!I12-'NG Alphas'!$C$2*'Demand by Case'!I$21 -> 0.53890978 | K15: ='Prices by Case'!J12*$C$1-'NG Alphas'!$C15*'Demand by Case'!J12-'NG Alphas'!$C$2*'Demand by Case'!J$21 -> 1.0608623 | L15: ='Prices by Case'!K12*$C$1-'NG Alphas'!$C15*'Demand by Case'!K12-'NG Alphas'!$C$2*'Demand by Case'!K$21 -> 0.74484405 | M15: ='Prices by Case'!L12*$C$1-'NG Alphas'!$C15*'Demand by Case'!L12-'NG Alphas'!$C$2*'Demand by Case'!L$21 -> -0.05079931 | N15: ='Prices by Case'!M12*$C$1-'NG Alphas'!$C15*'Demand by Case'!M12-'NG Alphas'!$C$2*'Demand by Case'!M$21 -> -0.50293649 | O15: ='Prices by Case'!N12*$C$1-'NG Alphas'!$C15*'Demand by Case'!N12-'NG Alphas'!$C$2*'Demand by Case'!N$21 -> 1.3390133 | P15: ='Prices by Case'!O12*$C$1-'NG Alphas'!$C15*'Demand by Case'!O12-'NG Alphas'!$C$2*'Demand by Case'!O$21 -> 2.0225775 | Q15: ='Prices by Case'!P12*$C$1-'NG Alphas'!$C15*'Demand by Case'!P12-'NG Alphas'!$C$2*'Demand by Case'!P$21 -> -0.53250915 | ... AR15: ='Prices by Case'!AQ12*$C$1-'NG Alphas'!$C15*'Demand by Case'!AQ12-'NG Alphas'!$C$2*'Demand by Case'!AQ$21 -> -1.2304545 | AT15: =(AH15+'Demand by Case'!AG12*'NG Alphas'!C15+'Demand by Case'!$AG$21*'NG Alphas'!$C$2)/'NG Alphas'!$C$1 -> 2.765788 | AU15: 4.067107
A16: High O&G Resource | B16: East South Central | C16: 0.60841227 | D16: ='Prices by Case'!C13*$C$1 -> 4.1378736 | E16: ='Prices by Case'!D13*$C$1-'NG Alphas'!$C16*'Demand by Case'!D13-'NG Alphas'!$C$2*'Demand by Case'!D$11 -> 2.2002798 | F16: ='Prices by Case'!E13*$C$1-'NG Alphas'!$C16*'Demand by Case'!E13-'NG Alphas'!$C$2*'Demand by Case'!E$11 -> 0.77014557 | G16: ='Prices by Case'!F13*$C$1-'NG Alphas'!$C16*'Demand by Case'!F13-'NG Alphas'!$C$2*'Demand by Case'!F$11 -> 1.7575023 | H16: ='Prices by Case'!G13*$C$1-'NG Alphas'!$C16*'Demand by Case'!G13-'NG Alphas'!$C$2*'Demand by Case'!G$11 -> 2.1929869 | I16: ='Prices by Case'!H13*$C$1-'NG Alphas'!$C16*'Demand by Case'!H13-'NG Alphas'!$C$2*'Demand by Case'!H$11 -> 0.429196 | J16: ='Prices by Case'!I13*$C$1-'NG Alphas'!$C16*'Demand by Case'!I13-'NG Alphas'!$C$2*'Demand by Case'!I$21 -> 0.039588121 | K16: ='Prices by Case'!J13*$C$1-'NG Alphas'!$C16*'Demand by Case'!J13-'NG Alphas'!$C$2*'Demand by Case'!J$21 -> 0.60453658 | L16: ='Prices by Case'!K13*$C$1-'NG Alphas'!$C16*'Demand by Case'!K13-'NG Alphas'!$C$2*'Demand by Case'!K$21 -> 0.3689439 | M16: ='Prices by Case'!L13*$C$1-'NG Alphas'!$C16*'Demand by Case'!L13-'NG Alphas'!$C$2*'Demand by Case'!L$21 -> -0.23416557 | N16: ='Prices by Case'!M13*$C$1-'NG Alphas'!$C16*'Demand by Case'!M13-'NG Alphas'!$C$2*'Demand by Case'!M$21 -> -0.60444316 | O16: ='Prices by Case'!N13*$C$1-'NG Alphas'!$C16*'Demand by Case'!N13-'NG Alphas'!$C$2*'Demand by Case'!N$21 -> 1.5068785 | P16: ='Prices by Case'!O13*$C$1-'NG Alphas'!$C16*'Demand by Case'!O13-'NG Alphas'!$C$2*'Demand by Case'!O$21 -> 2.5710225 | Q16: ='Prices by Case'!P13*$C$1-'NG Alphas'!$C16*'Demand by Case'!P13-'NG Alphas'!$C$2*'Demand by Case'!P$21 -> -0.63998441 | ... AR16: ='Prices by Case'!AQ13*$C$1-'NG Alphas'!$C16*'Demand by Case'!AQ13-'NG Alphas'!$C$2*'Demand by Case'!AQ$21 -> -0.81588888 | AT16: =(AH16+'Demand by Case'!AG13*'NG Alphas'!C16+'Demand by Case'!$AG$21*'NG Alphas'!$C$2)/'NG Alphas'!$C$1 -> 3.249156 | AU16: 3.465214
A17: High O&G Resource | B17: Middle Atlantic | C17: 0.14497775 | D17: ='Prices by Case'!C14*$C$1 -> 4.7115638 | E17: ='Prices by Case'!D14*$C$1-'NG Alphas'!$C17*'Demand by Case'!D14-'NG Alphas'!$C$2*'Demand by Case'!D$11 -> 3.1398234 | F17: ='Prices by Case'!E14*$C$1-'NG Alphas'!$C17*'Demand by Case'!E14-'NG Alphas'!$C$2*'Demand by Case'!E$11 -> 1.5397672 | G17: ='Prices by Case'!F14*$C$1-'NG Alphas'!$C17*'Demand by Case'!F14-'NG Alphas'!$C$2*'Demand by Case'!F$11 -> 2.465455 | H17: ='Prices by Case'!G14*$C$1-'NG Alphas'!$C17*'Demand by Case'!G14-'NG Alphas'!$C$2*'Demand by Case'!G$11 -> 2.7714772 | I17: ='Prices by Case'!H14*$C$1-'NG Alphas'!$C17*'Demand by Case'!H14-'NG Alphas'!$C$2*'Demand by Case'!H$11 -> 0.79368306 | J17: ='Prices by Case'!I14*$C$1-'NG Alphas'!$C17*'Demand by Case'!I14-'NG Alphas'!$C$2*'Demand by Case'!I$21 -> 0.61804108 | K17: ='Prices by Case'!J14*$C$1-'NG Alphas'!$C17*'Demand by Case'!J14-'NG Alphas'!$C$2*'Demand by Case'!J$21 -> 1.0452689 | L17: ='Prices by Case'!K14*$C$1-'NG Alphas'!$C17*'Demand by Case'!K14-'NG Alphas'!$C$2*'Demand by Case'!K$21 -> 0.90758109 | M17: ='Prices by Case'!L14*$C$1-'NG Alphas'!$C17*'Demand by Case'!L14-'NG Alphas'!$C$2*'Demand by Case'!L$21 -> 0.34902582 | N17: ='Prices by Case'!M14*$C$1-'NG Alphas'!$C17*'Demand by Case'!M14-'NG Alphas'!$C$2*'Demand by Case'!M$21 -> -0.12049963 | O17: ='Prices by Case'!N14*$C$1-'NG Alphas'!$C17*'Demand by Case'!N14-'NG Alphas'!$C$2*'Demand by Case'!N$21 -> 1.4511305 | P17: ='Prices by Case'!O14*$C$1-'NG Alphas'!$C17*'Demand by Case'!O14-'NG Alphas'!$C$2*'Demand by Case'!O$21 -> 1.7828926 | Q17: ='Prices by Case'!P14*$C$1-'NG Alphas'!$C17*'Demand by Case'!P14-'NG Alphas'!$C$2*'Demand by Case'!P$21 -> -0.127585 | ... AR17: ='Prices by Case'!AQ14*$C$1-'NG Alphas'!$C17*'Demand by Case'!AQ14-'NG Alphas'!$C$2*'Demand by Case'!AQ$21 -> -0.86868651 | AT17: =(AH17+'Demand by Case'!AG14*'NG Alphas'!C17+'Demand by Case'!$AG$21*'NG Alphas'!$C$2)/'NG Alphas'!$C$1 -> 2.542018 | AU17: 3.734132
A18: High O&G Resource | B18: Mountain | C18: 0.54532052 | D18: ='Prices by Case'!C15*$C$1 -> 4.348851 | E18: ='Prices by Case'!D15*$C$1-'NG Alphas'!$C18*'Demand by Case'!D15-'NG Alphas'!$C$2*'Demand by Case'!D$11 -> 2.7158125 | F18: ='Prices by Case'!E15*$C$1-'NG Alphas'!$C18*'Demand by Case'!E15-'NG Alphas'!$C$2*'Demand by Case'!E$11 -> 1.2803754 | G18: ='Prices by Case'!F15*$C$1-'NG Alphas'!$C18*'Demand by Case'!F15-'NG Alphas'!$C$2*'Demand by Case'!F$11 -> 2.1476221 | H18: ='Prices by Case'!G15*$C$1-'NG Alphas'!$C18*'Demand by Case'!G15-'NG Alphas'!$C$2*'Demand by Case'!G$11 -> 2.4511279 | I18: ='Prices by Case'!H15*$C$1-'NG Alphas'!$C18*'Demand by Case'!H15-'NG Alphas'!$C$2*'Demand by Case'!H$11 -> 0.82455363 | J18: ='Prices by Case'!I15*$C$1-'NG Alphas'!$C18*'Demand by Case'!I15-'NG Alphas'!$C$2*'Demand by Case'!I$21 -> 0.32504394 | K18: ='Prices by Case'!J15*$C$1-'NG Alphas'!$C18*'Demand by Case'!J15-'NG Alphas'!$C$2*'Demand by Case'!J$21 -> 0.86366943 | L18: ='Prices by Case'!K15*$C$1-'NG Alphas'!$C18*'Demand by Case'!K15-'NG Alphas'!$C$2*'Demand by Case'!K$21 -> 0.73171209 | M18: ='Prices by Case'!L15*$C$1-'NG Alphas'!$C18*'Demand by Case'!L15-'NG Alphas'!$C$2*'Demand by Case'!L$21 -> 0.012359993 | N18: ='Prices by Case'!M15*$C$1-'NG Alphas'!$C18*'Demand by Case'!M15-'NG Alphas'!$C$2*'Demand by Case'!M$21 -> -0.27958468 | O18: ='Prices by Case'!N15*$C$1-'NG Alphas'!$C18*'Demand by Case'!N15-'NG Alphas'!$C$2*'Demand by Case'!N$21 -> 1.760392 | P18: ='Prices by Case'!O15*$C$1-'NG Alphas'!$C18*'Demand by Case'!O15-'NG Alphas'!$C$2*'Demand by Case'!O$21 -> 2.5451021 | Q18: ='Prices by Case'!P15*$C$1-'NG Alphas'!$C18*'Demand by Case'!P15-'NG Alphas'!$C$2*'Demand by Case'!P$21 -> -0.29602426 | ... AR18: ='Prices by Case'!AQ15*$C$1-'NG Alphas'!$C18*'Demand by Case'!AQ15-'NG Alphas'!$C$2*'Demand by Case'!AQ$21 -> -0.076279579 | AT18: =(AH18+'Demand by Case'!AG15*'NG Alphas'!C18+'Demand by Case'!$AG$21*'NG Alphas'!$C$2)/'NG Alphas'!$C$1 -> 4.291714 | AU18: 4.308568
A19: High O&G Resource | B19: New England | C19: 0.5021758 | D19: ='Prices by Case'!C16*$C$1 -> 4.683875 | E19: ='Prices by Case'!D16*$C$1-'NG Alphas'!$C19*'Demand by Case'!D16-'NG Alphas'!$C$2*'Demand by Case'!D$11 -> 2.9271621 | F19: ='Prices by Case'!E16*$C$1-'NG Alphas'!$C19*'Demand by Case'!E16-'NG Alphas'!$C$2*'Demand by Case'!E$11 -> 1.6056841 | G19: ='Prices by Case'!F16*$C$1-'NG Alphas'!$C19*'Demand by Case'!F16-'NG Alphas'!$C$2*'Demand by Case'!F$11 -> 3.5464152 | H19: ='Prices by Case'!G16*$C$1-'NG Alphas'!$C19*'Demand by Case'!G16-'NG Alphas'!$C$2*'Demand by Case'!G$11 -> 3.9811656 | I19: ='Prices by Case'!H16*$C$1-'NG Alphas'!$C19*'Demand by Case'!H16-'NG Alphas'!$C$2*'Demand by Case'!H$11 -> 1.8666084 | J19: ='Prices by Case'!I16*$C$1-'NG Alphas'!$C19*'Demand by Case'!I16-'NG Alphas'!$C$2*'Demand by Case'!I$21 -> 1.5119946 | K19: ='Prices by Case'!J16*$C$1-'NG Alphas'!$C19*'Demand by Case'!J16-'NG Alphas'!$C$2*'Demand by Case'!J$21 -> 1.7528551 | L19: ='Prices by Case'!K16*$C$1-'NG Alphas'!$C19*'Demand by Case'!K16-'NG Alphas'!$C$2*'Demand by Case'!K$21 -> 1.89132 | M19: ='Prices by Case'!L16*$C$1-'NG Alphas'!$C19*'Demand by Case'!L16-'NG Alphas'!$C$2*'Demand by Case'!L$21 -> 1.5389976 | N19: ='Prices by Case'!M16*$C$1-'NG Alphas'!$C19*'Demand by Case'!M16-'NG Alphas'!$C$2*'Demand by Case'!M$21 -> 1.1313272 | O19: ='Prices by Case'!N16*$C$1-'NG Alphas'!$C19*'Demand by Case'!N16-'NG Alphas'!$C$2*'Demand by Case'!N$21 -> 3.0996412 | P19: ='Prices by Case'!O16*$C$1-'NG Alphas'!$C19*'Demand by Case'!O16-'NG Alphas'!$C$2*'Demand by Case'!O$21 -> 3.5483197 | Q19: ='Prices by Case'!P16*$C$1-'NG Alphas'!$C19*'Demand by Case'!P16-'NG Alphas'!$C$2*'Demand by Case'!P$21 -> 1.1978493 | ... AR19: ='Prices by Case'!AQ16*$C$1-'NG Alphas'!$C19*'Demand by Case'!AQ16-'NG Alphas'!$C$2*'Demand by Case'!AQ$21 -> -0.31724019 | AT19: =(AH19+'Demand by Case'!AG16*'NG Alphas'!C19+'Demand by Case'!$AG$21*'NG Alphas'!$C$2)/'NG Alphas'!$C$1 -> 3.172366 | AU19: 4.60398
A20: High O&G Resource | B20: Pacific | C20: 0.1968425 | D20: ='Prices by Case'!C17*$C$1 -> 4.1725022 | E20: ='Prices by Case'!D17*$C$1-'NG Alphas'!$C20*'Demand by Case'!D17-'NG Alphas'!$C$2*'Demand by Case'!D$11 -> 2.7320029 | F20: ='Prices by Case'!E17*$C$1-'NG Alphas'!$C20*'Demand by Case'!E17-'NG Alphas'!$C$2*'Demand by Case'!E$11 -> 1.5382517 | G20: ='Prices by Case'!F17*$C$1-'NG Alphas'!$C20*'Demand by Case'!F17-'NG Alphas'!$C$2*'Demand by Case'!F$11 -> 2.2558133 | H20: ='Prices by Case'!G17*$C$1-'NG Alphas'!$C20*'Demand by Case'!G17-'NG Alphas'!$C$2*'Demand by Case'!G$11 -> 2.665739 | I20: ='Prices by Case'!H17*$C$1-'NG Alphas'!$C20*'Demand by Case'!H17-'NG Alphas'!$C$2*'Demand by Case'!H$11 -> 1.0415252 | J20: ='Prices by Case'!I17*$C$1-'NG Alphas'!$C20*'Demand by Case'!I17-'NG Alphas'!$C$2*'Demand by Case'!I$21 -> 0.63590778 | K20: ='Prices by Case'!J17*$C$1-'NG Alphas'!$C20*'Demand by Case'!J17-'NG Alphas'!$C$2*'Demand by Case'!J$21 -> 1.0709235 | L20: ='Prices by Case'!K17*$C$1-'NG Alphas'!$C20*'Demand by Case'!K17-'NG Alphas'!$C$2*'Demand by Case'!K$21 -> 0.97809027 | M20: ='Prices by Case'!L17*$C$1-'NG Alphas'!$C20*'Demand by Case'!L17-'NG Alphas'!$C$2*'Demand by Case'!L$21 -> 0.50351144 | N20: ='Prices by Case'!M17*$C$1-'NG Alphas'!$C20*'Demand by Case'!M17-'NG Alphas'!$C$2*'Demand by Case'!M$21 -> 0.18755021 | O20: ='Prices by Case'!N17*$C$1-'NG Alphas'!$C20*'Demand by Case'!N17-'NG Alphas'!$C$2*'Demand by Case'!N$21 -> 2.353562 | P20: ='Prices by Case'!O17*$C$1-'NG Alphas'!$C20*'Demand by Case'!O17-'NG Alphas'!$C$2*'Demand by Case'!O$21 -> 3.0295754 | Q20: ='Prices by Case'!P17*$C$1-'NG Alphas'!$C20*'Demand by Case'!P17-'NG Alphas'!$C$2*'Demand by Case'!P$21 -> 0.19857816 | ... AR20: ='Prices by Case'!AQ17*$C$1-'NG Alphas'!$C20*'Demand by Case'!AQ17-'NG Alphas'!$C$2*'Demand by Case'!AQ$21 -> 0.63115776 | AT20: =(AH20+'Demand by Case'!AG17*'NG Alphas'!C20+'Demand by Case'!$AG$21*'NG Alphas'!$C$2)/'NG Alphas'!$C$1 -> 4.376058 | AU20: 3.768217
A21: High O&G Resource | B21: South Atlantic | C21: 0.16186349 | D21: ='Prices by Case'!C18*$C$1 -> 5.2114045 | E21: ='Prices by Case'!D18*$C$1-'NG Alphas'!$C21*'Demand by Case'!D18-'NG Alphas'!$C$2*'Demand by Case'!D$11 -> 3.2690963 | F21: ='Prices by Case'!E18*$C$1-'NG Alphas'!$C21*'Demand by Case'!E18-'NG Alphas'!$C$2*'Demand by Case'!E$11 -> 1.8726286 | G21: ='Prices by Case'!F18*$C$1-'NG Alphas'!$C21*'Demand by Case'!F18-'NG Alphas'!$C$2*'Demand by Case'!F$11 -> 2.4758235 | H21: ='Prices by Case'!G18*$C$1-'NG Alphas'!$C21*'Demand by Case'!G18-'NG Alphas'!$C$2*'Demand by Case'!G$11 -> 2.910621 | I21: ='Prices by Case'!H18*$C$1-'NG Alphas'!$C21*'Demand by Case'!H18-'NG Alphas'!$C$2*'Demand by Case'!H$11 -> 1.4151553 | J21: ='Prices by Case'!I18*$C$1-'NG Alphas'!$C21*'Demand by Case'!I18-'NG Alphas'!$C$2*'Demand by Case'!I$21 -> 0.92748952 | K21: ='Prices by Case'!J18*$C$1-'NG Alphas'!$C21*'Demand by Case'!J18-'NG Alphas'!$C$2*'Demand by Case'!J$21 -> 1.247641 | L21: ='Prices by Case'!K18*$C$1-'NG Alphas'!$C21*'Demand by Case'!K18-'NG Alphas'!$C$2*'Demand by Case'!K$21 -> 0.96584 | M21: ='Prices by Case'!L18*$C$1-'NG Alphas'!$C21*'Demand by Case'!L18-'NG Alphas'!$C$2*'Demand by Case'!L$21 -> 0.42709666 | N21: ='Prices by Case'!M18*$C$1-'NG Alphas'!$C21*'Demand by Case'!M18-'NG Alphas'!$C$2*'Demand by Case'!M$21 -> 0.045345631 | O21: ='Prices by Case'!N18*$C$1-'NG Alphas'!$C21*'Demand by Case'!N18-'NG Alphas'!$C$2*'Demand by Case'!N$21 -> 2.0804123 | P21: ='Prices by Case'!O18*$C$1-'NG Alphas'!$C21*'Demand by Case'!O18-'NG Alphas'!$C$2*'Demand by Case'!O$21 -> 3.0785934 | Q21: ='Prices by Case'!P18*$C$1-'NG Alphas'!$C21*'Demand by Case'!P18-'NG Alphas'!$C$2*'Demand by Case'!P$21 -> 0.048011954 | ... AR21: ='Prices by Case'!AQ18*$C$1-'NG Alphas'!$C21*'Demand by Case'!AQ18-'NG Alphas'!$C$2*'Demand by Case'!AQ$21 -> 0.0089009141 | AT21: =(AH21+'Demand by Case'!AG18*'NG Alphas'!C21+'Demand by Case'!$AG$21*'NG Alphas'!$C$2)/'NG Alphas'!$C$1 -> 3.826042 | AU21: 3.4382
